Workbook

Sheet Vic20 BD tiles plan
A1: Unique Sprite | B1: Comments | C1: Characters needed | D1: Plan
A2: Space | B2: Use space character 4 times | C2: 1
A3: Dirt | C3: 4
A4: Wall | B4: Can reuse one mapped tile 4 times | C4: 2 | D4: 2 characters applied 2 times
A5: Steel Wall | B5: Can reuse one mapped tile 4 times | C5: 1 | D5: 1 character applied 4 times
A6: Diamond 1 | C6: 4
A7: Diamond 2 | C7: 4
A8: Diamond 3 | C8: 4
A9: Diamond 4 | C9: 4
A10: Boulder 1 | C10: 4
A11: Boulder 2 | C11: 4
A12: Firefly 1 | C12: 4
A13: Firefly 2 | C13: 4
A14: Firefly 3 | C14: 4
A15: Firefly 4 | C15: 4
A16: Amoeba 1 | C16: 4
A17: Amoeba 2 | C17: 4
... A23: Explosion 4 | C23: 4
A24: Magic Wall 1 | B24: Also used for expanding wall | C24: 2 | D24: 2 characters applied 2 times
A25: Magic Wall 2 | C25: 2 | D25: 2 characters applied 2 times
A26: Magic Wall 3 | C26: 2 | D26: 2 characters applied 2 times
A27: Magic Wall 4 | C27: 2 | D27: 2 characters applied 2 times
A28: Butterfly 1 | C28: 4
A29: Butterfly 2 | C29: 4
A30: Butterfly 3 | C30: 4
A31: Boulder 3 | B31: aka Bubble | C31: 4
A32: Rockford 1 | C32: 4
A33: Rockford 2 (blink 1) | B33: Reuse feet | C33: 2
A34: Rockford 3 (blink 2) | B34: Reuse feet | C34: 2
A35: Rockford 4 (wink 1) | B35: Reuse head in blink 1 (one side), reuse feet | C35: 0
A36: Rockford 5 (wink 2) | B36: Reuse head in blink 2 (one side), reuse feet | C36: 0
A37: Rockford 6 (wait 1) | B37: Reuse head | C37: 2
A38: Rockford 7 (wait 2) | B38: Reuse head | C38: 1
A39: Rockford 8 (wait 3) | B39: Reuse head in blink 1, reuse feet in wait 1 | C39: 0
A40: Rockford 9 (wait 4) | B40: Reuse head in blink 2, reuse feet in wait 2 | C40: 0
A41: Rockford 10 (wait 5) | B41: Reuse head in blink 2, reuse feet in wait 1 | C41: 0
A42: Rockford 11 (left 1) | C42: 4
A43: Rockford 12 (left 2) | B43: Reuse head left | C43: 2
A44: Rockford 13 (left 3) | B44: Reuse head left | C44: 2
A45: Rockford 14 (left 4) | B45: Reuse head left | C45: 1
...

Sheet Vic20 tiles
A1: Pathway | AJ1: =";"&PROPER(A1) -> ;Pathway
B2: 0 | C2: 0 | D2: 0 | E2: 0 | F2: 0 | G2: 0 | H2: 0 | I2: 0 | K2: =DEC2BIN(B2,2) -> 00 | L2: =DEC2BIN(C2,2) -> 00 | M2: =DEC2BIN(D2,2) -> 00 | N2: =DEC2BIN(E2,2) -> 00 | O2: =DEC2BIN(F2,2) -> 00 | P2: =DEC2BIN(G2,2) -> 00 | Q2: =DEC2BIN(H2,2) -> 00 | R2: =DEC2BIN(I2,2) -> 00 | T2: =_xlfn.CONCAT(K2:R2) -> 0000000000000000 | V2: =LEFT(T2,8) -> 00000000 | W2: =RIGHT(T2,8) -> 00000000 | X2: =BIN2HEX(V2,2) -> 00 | Y2: =BIN2HEX(W2,2) -> 00 | AA2: {=TRANSPOSE(X2:X9)} -> 00 | AB2: 3F | AC2: 00 | AD2: 00 | AE2: 00 | AF2: FC | AG2: 00 | AH2: 00 | AJ2: =LOWER("!byte $"&AA2&", $"&AB2&", $"&AC2&", $"&AD2&", $"&AE2&", $"&AF2&", $"&AG2&", $"&AH2) -> !byte $00, $3f, $00, $00, $00, $fc, $00, $00
B3: 0 | C3: 3 | D3: 3 | E3: 3 | F3: 0 | G3: 3 | H3: 3 | I3: 0 | K3: =DEC2BIN(B3,2) -> 00 | L3: =DEC2BIN(C3,2) -> 11 | M3: =DEC2BIN(D3,2) -> 11 | N3: =DEC2BIN(E3,2) -> 11 | O3: =DEC2BIN(F3,2) -> 00 | P3: =DEC2BIN(G3,2) -> 11 | Q3: =DEC2BIN(H3,2) -> 11 | R3: =DEC2BIN(I3,2) -> 00 | T3: =_xlfn.CONCAT(K3:R3) -> 0011111100111100 | V3: =LEFT(T3,8) -> 00111111 | W3: =RIGHT(T3,8) -> 00111100 | X3: =BIN2HEX(V3,2) -> 3F | Y3: =BIN2HEX(W3,2) -> 3C | AA3: {=TRANSPOSE(X10:X17)} -> 00 | AB3: 33 | AC3: 00 | AD3: 00 | AE3: 00 | AF3: FC | AG3: 00 | AH3: 00 | AJ3: =LOWER("!byte $"&AA3&", $"&AB3&", $"&AC3&", $"&AD3&", $"&AE3&", $"&AF3&", $"&AG3&", $"&AH3) -> !byte $00, $33, $00, $00, $00, $fc, $00, $00
B4: 0 | C4: 0 | D4: 0 | E4: 0 | F4: 0 | G4: 0 | H4: 0 | I4: 0 | K4: =DEC2BIN(B4,2) -> 00 | L4: =DEC2BIN(C4,2) -> 00 | M4: =DEC2BIN(D4,2) -> 00 | N4: =DEC2BIN(E4,2) -> 00 | O4: =DEC2BIN(F4,2) -> 00 | P4: =DEC2BIN(G4,2) -> 00 | Q4: =DEC2BIN(H4,2) -> 00 | R4: =DEC2BIN(I4,2) -> 00 | T4: =_xlfn.CONCAT(K4:R4) -> 0000000000000000 | V4: =LEFT(T4,8) -> 00000000 | W4: =RIGHT(T4,8) -> 00000000 | X4: =BIN2HEX(V4,2) -> 00 | Y4: =BIN2HEX(W4,2) -> 00 | AA4: {=TRANSPOSE(Y2:Y9)} -> 00 | AB4: 3C | AC4: 00 | AD4: 00 | AE4: 00 | AF4: CC | AG4: 00 | AH4: 00 | AJ4: =LOWER("!byte $"&AA4&", $"&AB4&", $"&AC4&", $"&AD4&", $"&AE4&", $"&AF4&", $"&AG4&", $"&AH4) -> !byte $00, $3c, $00, $00, $00, $cc, $00, $00
B5: 0 | C5: 0 | D5: 0 | E5: 0 | F5: 0 | G5: 0 | H5: 0 | I5: 0 | K5: =DEC2BIN(B5,2) -> 00 | L5: =DEC2BIN(C5,2) -> 00 | M5: =DEC2BIN(D5,2) -> 00 | N5: =DEC2BIN(E5,2) -> 00 | O5: =DEC2BIN(F5,2) -> 00 | P5: =DEC2BIN(G5,2) -> 00 | Q5: =DEC2BIN(H5,2) -> 00 | R5: =DEC2BIN(I5,2) -> 00 | T5: =_xlfn.CONCAT(K5:R5) -> 0000000000000000 | V5: =LEFT(T5,8) -> 00000000 | W5: =RIGHT(T5,8) -> 00000000 | X5: =BIN2HEX(V5,2) -> 00 | Y5: =BIN2HEX(W5,2) -> 00 | AA5: {=TRANSPOSE(Y10:Y17)} -> 00 | AB5: CF | AC5: 00 | AD5: 00 | AE5: 00 | AF5: C3 | AG5: 00 | AH5: 00 | AJ5: =LOWER("!byte $"&AA5&", $"&AB5&", $"&AC5&", $"&AD5&", $"&AE5&", $"&AF5&", $"&AG5&", $"&AH5) -> !byte $00, $cf, $00, $00, $00, $c3, $00, $00
B6: 0 | C6: 0 | D6: 0 | E6: 0 | F6: 0 | G6: 0 | H6: 0 | I6: 0 | K6: =DEC2BIN(B6,2) -> 00 | L6: =DEC2BIN(C6,2) -> 00 | M6: =DEC2BIN(D6,2) -> 00 | N6: =DEC2BIN(E6,2) -> 00 | O6: =DEC2BIN(F6,2) -> 00 | P6: =DEC2BIN(G6,2) -> 00 | Q6: =DEC2BIN(H6,2) -> 00 | R6: =DEC2BIN(I6,2) -> 00 | T6: =_xlfn.CONCAT(K6:R6) -> 0000000000000000 | V6: =LEFT(T6,8) -> 00000000 | W6: =RIGHT(T6,8) -> 00000000 | X6: =BIN2HEX(V6,2) -> 00 | Y6: =BIN2HEX(W6,2) -> 00
B7: 3 | C7: 3 | D7: 3 | E7: 0 | F7: 3 | G7: 0 | H7: 3 | I7: 0 | K7: =DEC2BIN(B7,2) -> 11 | L7: =DEC2BIN(C7,2) -> 11 | M7: =DEC2BIN(D7,2) -> 11 | N7: =DEC2BIN(E7,2) -> 00 | O7: =DEC2BIN(F7,2) -> 11 | P7: =DEC2BIN(G7,2) -> 00 | Q7: =DEC2BIN(H7,2) -> 11 | R7: =DEC2BIN(I7,2) -> 00 | T7: =_xlfn.CONCAT(K7:R7) -> 1111110011001100 | V7: =LEFT(T7,8) -> 11111100 | W7: =RIGHT(T7,8) -> 11001100 | X7: =BIN2HEX(V7,2) -> FC | Y7: =BIN2HEX(W7,2) -> CC
B8: 0 | C8: 0 | D8: 0 | E8: 0 | F8: 0 | G8: 0 | H8: 0 | I8: 0 | K8: =DEC2BIN(B8,2) -> 00 | L8: =DEC2BIN(C8,2) -> 00 | M8: =DEC2BIN(D8,2) -> 00 | N8: =DEC2BIN(E8,2) -> 00 | O8: =DEC2BIN(F8,2) -> 00 | P8: =DEC2BIN(G8,2) -> 00 | Q8: =DEC2BIN(H8,2) -> 00 | R8: =DEC2BIN(I8,2) -> 00 | T8: =_xlfn.CONCAT(K8:R8) -> 0000000000000000 | V8: =LEFT(T8,8) -> 00000000 | W8: =RIGHT(T8,8) -> 00000000 | X8: =BIN2HEX(V8,2) -> 00 | Y8: =BIN2HEX(W8,2) -> 00
B9: 0 | C9: 0 | D9: 0 | E9: 0 | F9: 0 | G9: 0 | H9: 0 | I9: 0 | K9: =DEC2BIN(B9,2) -> 00 | L9: =DEC2BIN(C9,2) -> 00 | M9: =DEC2BIN(D9,2) -> 00 | N9: =DEC2BIN(E9,2) -> 00 | O9: =DEC2BIN(F9,2) -> 00 | P9: =DEC2BIN(G9,2) -> 00 | Q9: =DEC2BIN(H9,2) -> 00 | R9: =DEC2BIN(I9,2) -> 00 | T9: =_xlfn.CONCAT(K9:R9) -> 0000000000000000 | V9: =LEFT(T9,8) -> 00000000 | W9: =RIGHT(T9,8) -> 00000000 | X9: =BIN2HEX(V9,2) -> 00 | Y9: =BIN2HEX(W9,2) -> 00
B10: 0 | C10: 0 | D10: 0 | E10: 0 | F10: 0 | G10: 0 | H10: 0 | I10: 0 | K10: =DEC2BIN(B10,2) -> 00 | L10: =DEC2BIN(C10,2) -> 00 | M10: =DEC2BIN(D10,2) -> 00 | N10: =DEC2BIN(E10,2) -> 00 | O10: =DEC2BIN(F10,2) -> 00 | P10: =DEC2BIN(G10,2) -> 00 | Q10: =DEC2BIN(H10,2) -> 00 | R10: =DEC2BIN(I10,2) -> 00 | T10: =_xlfn.CONCAT(K10:R10) -> 0000000000000000 | V10: =LEFT(T10,8) -> 00000000 | W10: =RIGHT(T10,8) -> 00000000 | X10: =BIN2HEX(V10,2) -> 00 | Y10: =BIN2HEX(W10,2) -> 00
B11: 0 | C11: 3 | D11: 0 | E11: 3 | F11: 3 | G11: 0 | H11: 3 | I11: 3 | K11: =DEC2BIN(B11,2) -> 00 | L11: =DEC2BIN(C11,2) -> 11 | M11: =DEC2BIN(D11,2) -> 00 | N11: =DEC2BIN(E11,2) -> 11 | O11: =DEC2BIN(F11,2) -> 11 | P11: =DEC2BIN(G11,2) -> 00 | Q11: =DEC2BIN(H11,2) -> 11 | R11: =DEC2BIN(I11,2) -> 11 | T11: =_xlfn.CONCAT(K11:R11) -> 0011001111001111 | V11: =LEFT(T11,8) -> 00110011 | W11: =RIGHT(T11,8) -> 11001111 | X11: =BIN2HEX(V11,2) -> 33 | Y11: =BIN2HEX(W11,2) -> CF
B12: 0 | C12: 0 | D12: 0 | E12: 0 | F12: 0 | G12: 0 | H12: 0 | I12: 0 | K12: =DEC2BIN(B12,2) -> 00 | L12: =DEC2BIN(C12,2) -> 00 | M12: =DEC2BIN(D12,2) -> 00 | N12: =DEC2BIN(E12,2) -> 00 | O12: =DEC2BIN(F12,2) -> 00 | P12: =DEC2BIN(G12,2) -> 00 | Q12: =DEC2BIN(H12,2) -> 00 | R12: =DEC2BIN(I12,2) -> 00 | T12: =_xlfn.CONCAT(K12:R12) -> 0000000000000000 | V12: =LEFT(T12,8) -> 00000000 | W12: =RIGHT(T12,8) -> 00000000 | X12: =BIN2HEX(V12,2) -> 00 | Y12: =BIN2HEX(W12,2) -> 00
B13: 0 | C13: 0 | D13: 0 | E13: 0 | F13: 0 | G13: 0 | H13: 0 | I13: 0 | K13: =DEC2BIN(B13,2) -> 00 | L13: =DEC2BIN(C13,2) -> 00 | M13: =DEC2BIN(D13,2) -> 00 | N13: =DEC2BIN(E13,2) -> 00 | O13: =DEC2BIN(F13,2) -> 00 | P13: =DEC2BIN(G13,2) -> 00 | Q13: =DEC2BIN(H13,2) -> 00 | R13: =DEC2BIN(I13,2) -> 00 | T13: =_xlfn.CONCAT(K13:R13) -> 0000000000000000 | V13: =LEFT(T13,8) -> 00000000 | W13: =RIGHT(T13,8) -> 00000000 | X13: =BIN2HEX(V13,2) -> 00 | Y13: =BIN2HEX(W13,2) -> 00
B14: 0 | C14: 0 | D14: 0 | E14: 0 | F14: 0 | G14: 0 | H14: 0 | I14: 0 | K14: =DEC2BIN(B14,2) -> 00 | L14: =DEC2BIN(C14,2) -> 00 | M14: =DEC2BIN(D14,2) -> 00 | N14: =DEC2BIN(E14,2) -> 00 | O14: =DEC2BIN(F14,2) -> 00 | P14: =DEC2BIN(G14,2) -> 00 | Q14: =DEC2BIN(H14,2) -> 00 | R14: =DEC2BIN(I14,2) -> 00 | T14: =_xlfn.CONCAT(K14:R14) -> 0000000000000000 | V14: =LEFT(T14,8) -> 00000000 | W14: =RIGHT(T14,8) -> 00000000 | X14: =BIN2HEX(V14,2) -> 00 | Y14: =BIN2HEX(W14,2) -> 00
B15: 3 | C15: 3 | D15: 3 | E15: 0 | F15: 3 | G15: 0 | H15: 0 | I15: 3 | K15: =DEC2BIN(B15,2) -> 11 | L15: =DEC2BIN(C15,2) -> 11 | M15: =DEC2BIN(D15,2) -> 11 | N15: =DEC2BIN(E15,2) -> 00 | O15: =DEC2BIN(F15,2) -> 11 | P15: =DEC2BIN(G15,2) -> 00 | Q15: =DEC2BIN(H15,2) -> 00 | R15: =DEC2BIN(I15,2) -> 11 | T15: =_xlfn.CONCAT(K15:R15) -> 1111110011000011 | V15: =LEFT(T15,8) -> 11111100 | W15: =RIGHT(T15,8) -> 11000011 | X15: =BIN2HEX(V15,2) -> FC | Y15: =BIN2HEX(W15,2) -> C3
B16: 0 | C16: 0 | D16: 0 | E16: 0 | F16: 0 | G16: 0 | H16: 0 | I16: 0 | K16: =DEC2BIN(B16,2) -> 00 | L16: =DEC2BIN(C16,2) -> 00 | M16: =DEC2BIN(D16,2) -> 00 | N16: =DEC2BIN(E16,2) -> 00 | O16: =DEC2BIN(F16,2) -> 00 | P16: =DEC2BIN(G16,2) -> 00 | Q16: =DEC2BIN(H16,2) -> 00 | R16: =DEC2BIN(I16,2) -> 00 | T16: =_xlfn.CONCAT(K16:R16) -> 0000000000000000 | V16: =LEFT(T16,8) -> 00000000 | W16: =RIGHT(T16,8) -> 00000000 | X16: =BIN2HEX(V16,2) -> 00 | Y16: =BIN2HEX(W16,2) -> 00
B17: 0 | C17: 0 | D17: 0 | E17: 0 | F17: 0 | G17: 0 | H17: 0 | I17: 0 | K17: =DEC2BIN(B17,2) -> 00 | L17: =DEC2BIN(C17,2) -> 00 | M17: =DEC2BIN(D17,2) -> 00 | N17: =DEC2BIN(E17,2) -> 00 | O17: =DEC2BIN(F17,2) -> 00 | P17: =DEC2BIN(G17,2) -> 00 | Q17: =DEC2BIN(H17,2) -> 00 | R17: =DEC2BIN(I17,2) -> 00 | T17: =_xlfn.CONCAT(K17:R17) -> 0000000000000000 | V17: =LEFT(T17,8) -> 00000000 | W17: =RIGHT(T17,8) -> 00000000 | X17: =BIN2HEX(V17,2) -> 00 | Y17: =BIN2HEX(W17,2) -> 00
A18: Earth | AJ18: =";"&PROPER(A18) -> ;Earth
B19: 0 | C19: 0 | D19: 2 | E19: 0 | F19: 0 | G19: 2 | H19: 0 | I19: 2 | K19: =DEC2BIN(B19,2) -> 00 | L19: =DEC2BIN(C19,2) -> 00 | M19: =DEC2BIN(D19,2) -> 10 | N19: =DEC2BIN(E19,2) -> 00 | O19: =DEC2BIN(F19,2) -> 00 | P19: =DEC2BIN(G19,2) -> 10 | Q19: =DEC2BIN(H19,2) -> 00 | R19: =DEC2BIN(I19,2) -> 10 | T19: =_xlfn.CONCAT(K19:R19) -> 0000100000100010 | V19: =LEFT(T19,8) -> 00001000 | W19: =RIGHT(T19,8) -> 00100010 | X19: =BIN2HEX(V19,2) -> 08 | Y19: =BIN2HEX(W19,2) -> 22 | AA19: {=TRANSPOSE(X19:X26)} -> 08 | AB19: A0 | AC19: 2A | AD19: A2 | AE19: 8A | AF19: 28 | AG19: AA | AH19: 8A | AJ19: =LOWER("!byte $"&AA19&", $"&AB19&", $"&AC19&", $"&AD19&", $"&AE19&", $"&AF19&", $"&AG19&", $"&AH19) -> !byte $08, $a0, $2a, $a2, $8a, $28, $aa, $8a
B20: 2 | C20: 2 | D20: 0 | E20: 0 | F20: 2 | G20: 0 | H20: 0 | I20: 2 | K20: =DEC2BIN(B20,2) -> 10 | L20: =DEC2BIN(C20,2) -> 10 | M20: =DEC2BIN(D20,2) -> 00 | N20: =DEC2BIN(E20,2) -> 00 | O20: =DEC2BIN(F20,2) -> 10 | P20: =DEC2BIN(G20,2) -> 00 | Q20: =DEC2BIN(H20,2) -> 00 | R20: =DEC2BIN(I20,2) -> 10 | T20: =_xlfn.CONCAT(K20:R20) -> 1010000010000010 | V20: =LEFT(T20,8) -> 10100000 | W20: =RIGHT(T20,8) -> 10000010 | X20: =BIN2HEX(V20,2) -> A0 | Y20: =BIN2HEX(W20,2) -> 82 | AA20: {=TRANSPOSE(X27:X34)} -> 2A | AB20: A2 | AC20: A8 | AD20: 2A | AE20: 88 | AF20: A0 | AG20: 8A | AH20: 20 | AJ20: =LOWER("!byte $"&AA20&", $"&AB20&", $"&AC20&", $"&AD20&", $"&AE20&", $"&AF20&", $"&AG20&", $"&AH20) -> !byte $2a, $a2, $a8, $2a, $88, $a0, $8a, $20
B21: 0 | C21: 2 | D21: 2 | E21: 2 | F21: 0 | G21: 2 | H21: 2 | I21: 0 | K21: =DEC2BIN(B21,2) -> 00 | L21: =DEC2BIN(C21,2) -> 10 | M21: =DEC2BIN(D21,2) -> 10 | N21: =DEC2BIN(E21,2) -> 10 | O21: =DEC2BIN(F21,2) -> 00 | P21: =DEC2BIN(G21,2) -> 10 | Q21: =DEC2BIN(H21,2) -> 10 | R21: =DEC2BIN(I21,2) -> 00 | T21: =_xlfn.CONCAT(K21:R21) -> 0010101000101000 | V21: =LEFT(T21,8) -> 00101010 | W21: =RIGHT(T21,8) -> 00101000 | X21: =BIN2HEX(V21,2) -> 2A | Y21: =BIN2HEX(W21,2) -> 28 | AA21: {=TRANSPOSE(Y19:Y26)} -> 22 | AB21: 82 | AC21: 28 | AD21: A2 | AE21: 8A | AF21: A8 | AG21: 8A | AH21: A8 | AJ21: =LOWER("!byte $"&AA21&", $"&AB21&", $"&AC21&", $"&AD21&", $"&AE21&", $"&AF21&", $"&AG21&", $"&AH21) -> !byte $22, $82, $28, $a2, $8a, $a8, $8a, $a8
B22: 2 | C22: 2 | D22: 0 | E22: 2 | F22: 2 | G22: 2 | H22: 0 | I22: 2 | K22: =DEC2BIN(B22,2) -> 10 | L22: =DEC2BIN(C22,2) -> 10 | M22: =DEC2BIN(D22,2) -> 00 | N22: =DEC2BIN(E22,2) -> 10 | O22: =DEC2BIN(F22,2) -> 10 | P22: =DEC2BIN(G22,2) -> 10 | Q22: =DEC2BIN(H22,2) -> 00 | R22: =DEC2BIN(I22,2) -> 10 | T22: =_xlfn.CONCAT(K22:R22) -> 1010001010100010 | V22: =LEFT(T22,8) -> 10100010 | W22: =RIGHT(T22,8) -> 10100010 | X22: =BIN2HEX(V22,2) -> A2 | Y22: =BIN2HEX(W22,2) -> A2 | AA22: {=TRANSPOSE(Y27:Y34)} -> AA | AB22: A8 | AC22: A2 | AD22: 2A | AE22: 88 | AF22: A2 | AG22: 20 | AH22: 88 | AJ22: =LOWER("!byte $"&AA22&", $"&AB22&", $"&AC22&", $"&AD22&", $"&AE22&", $"&AF22&", $"&AG22&", $"&AH22) -> !byte $aa, $a8, $a2, $2a, $88, $a2, $20, $88
B23: 2 | C23: 0 | D23: 2 | E23: 2 | F23: 2 | G23: 0 | H23: 2 | I23: 2 | K23: =DEC2BIN(B23,2) -> 10 | L23: =DEC2BIN(C23,2) -> 00 | M23: =DEC2BIN(D23,2) -> 10 | N23: =DEC2BIN(E23,2) -> 10 | O23: =DEC2BIN(F23,2) -> 10 | P23: =DEC2BIN(G23,2) -> 00 | Q23: =DEC2BIN(H23,2) -> 10 | R23: =DEC2BIN(I23,2) -> 10 | T23: =_xlfn.CONCAT(K23:R23) -> 1000101010001010 | V23: =LEFT(T23,8) -> 10001010 | W23: =RIGHT(T23,8) -> 10001010 | X23: =BIN2HEX(V23,2) -> 8A | Y23: =BIN2HEX(W23,2) -> 8A
B24: 0 | C24: 2 | D24: 2 | E24: 0 | F24: 2 | G24: 2 | H24: 2 | I24: 0 | K24: =DEC2BIN(B24,2) -> 00 | L24: =DEC2BIN(C24,2) -> 10 | M24: =DEC2BIN(D24,2) -> 10 | N24: =DEC2BIN(E24,2) -> 00 | O24: =DEC2BIN(F24,2) -> 10 | P24: =DEC2BIN(G24,2) -> 10 | Q24: =DEC2BIN(H24,2) -> 10 | R24: =DEC2BIN(I24,2) -> 00 | T24: =_xlfn.CONCAT(K24:R24) -> 0010100010101000 | V24: =LEFT(T24,8) -> 00101000 | W24: =RIGHT(T24,8) -> 10101000 | X24: =BIN2HEX(V24,2) -> 28 | Y24: =BIN2HEX(W24,2) -> A8
B25: 2 | C25: 2 | D25: 2 | E25: 2 | F25: 2 | G25: 0 | H25: 2 | I25: 2 | K25: =DEC2BIN(B25,2) -> 10 | L25: =DEC2BIN(C25,2) -> 10 | M25: =DEC2BIN(D25,2) -> 10 | N25: =DEC2BIN(E25,2) -> 10 | O25: =DEC2BIN(F25,2) -> 10 | P25: =DEC2BIN(G25,2) -> 00 | Q25: =DEC2BIN(H25,2) -> 10 | R25: =DEC2BIN(I25,2) -> 10 | T25: =_xlfn.CONCAT(K25:R25) -> 1010101010001010 | V25: =LEFT(T25,8) -> 10101010 | W25: =RIGHT(T25,8) -> 10001010 | X25: =BIN2HEX(V25,2) -> AA | Y25: =BIN2HEX(W25,2) -> 8A
B26: 2 | C26: 0 | D26: 2 | E26: 2 | F26: 2 | G26: 2 | H26: 2 | I26: 0 | K26: =DEC2BIN(B26,2) -> 10 | L26: =DEC2BIN(C26,2) -> 00 | M26: =DEC2BIN(D26,2) -> 10 | N26: =DEC2BIN(E26,2) -> 10 | O26: =DEC2BIN(F26,2) -> 10 | P26: =DEC2BIN(G26,2) -> 10 | Q26: =DEC2BIN(H26,2) -> 10 | R26: =DEC2BIN(I26,2) -> 00 | T26: =_xlfn.CONCAT(K26:R26) -> 1000101010101000 | V26: =LEFT(T26,8) -> 10001010 | W26: =RIGHT(T26,8) -> 10101000 | X26: =BIN2HEX(V26,2) -> 8A | Y26: =BIN2HEX(W26,2) -> A8
B27: 0 | C27: 2 | D27: 2 | E27: 2 | F27: 2 | G27: 2 | H27: 2 | I27: 2 | K27: =DEC2BIN(B27,2) -> 00 | L27: =DEC2BIN(C27,2) -> 10 | M27: =DEC2BIN(D27,2) -> 10 | N27: =DEC2BIN(E27,2) -> 10 | O27: =DEC2BIN(F27,2) -> 10 | P27: =DEC2BIN(G27,2) -> 10 | Q27: =DEC2BIN(H27,2) -> 10 | R27: =DEC2BIN(I27,2) -> 10 | T27: =_xlfn.CONCAT(K27:R27) -> 0010101010101010 | V27: =LEFT(T27,8) -> 00101010 | W27: =RIGHT(T27,8) -> 10101010 | X27: =BIN2HEX(V27,2) -> 2A | Y27: =BIN2HEX(W27,2) -> AA
B28: 2 | C28: 2 | D28: 0 | E28: 2 | F28: 2 | G28: 2 | H28: 2 | I28: 0 | K28: =DEC2BIN(B28,2) -> 10 | L28: =DEC2BIN(C28,2) -> 10 | M28: =DEC2BIN(D28,2) -> 00 | N28: =DEC2BIN(E28,2) -> 10 | O28: =DEC2BIN(F28,2) -> 10 | P28: =DEC2BIN(G28,2) -> 10 | Q28: =DEC2BIN(H28,2) -> 10 | R28: =DEC2BIN(I28,2) -> 00 | T28: =_xlfn.CONCAT(K28:R28) -> 1010001010101000 | V28: =LEFT(T28,8) -> 10100010 | W28: =RIGHT(T28,8) -> 10101000 | X28: =BIN2HEX(V28,2) -> A2 | Y28: =BIN2HEX(W28,2) -> A8
B29: 2 | C29: 2 | D29: 2 | E29: 0 | F29: 2 | G29: 2 | H29: 0 | I29: 2 | K29: =DEC2BIN(B29,2) -> 10 | L29: =DEC2BIN(C29,2) -> 10 | M29: =DEC2BIN(D29,2) -> 10 | N29: =DEC2BIN(E29,2) -> 00 | O29: =DEC2BIN(F29,2) -> 10 | P29: =DEC2BIN(G29,2) -> 10 | Q29: =DEC2BIN(H29,2) -> 00 | R29: =DEC2BIN(I29,2) -> 10 | T29: =_xlfn.CONCAT(K29:R29) -> 1010100010100010 | V29: =LEFT(T29,8) -> 10101000 | W29: =RIGHT(T29,8) -> 10100010 | X29: =BIN2HEX(V29,2) -> A8 | Y29: =BIN2HEX(W29,2) -> A2
B30: 0 | C30: 2 | D30: 2 | E30: 2 | F30: 0 | G30: 2 | H30: 2 | I30: 2 | K30: =DEC2BIN(B30,2) -> 00 | L30: =DEC2BIN(C30,2) -> 10 | M30: =DEC2BIN(D30,2) -> 10 | N30: =DEC2BIN(E30,2) -> 10 | O30: =DEC2BIN(F30,2) -> 00 | P30: =DEC2BIN(G30,2) -> 10 | Q30: =DEC2BIN(H30,2) -> 10 | R30: =DEC2BIN(I30,2) -> 10 | T30: =_xlfn.CONCAT(K30:R30) -> 0010101000101010 | V30: =LEFT(T30,8) -> 00101010 | W30: =RIGHT(T30,8) -> 00101010 | X30: =BIN2HEX(V30,2) -> 2A | Y30: =BIN2HEX(W30,2) -> 2A
B31: 2 | C31: 0 | D31: 2 | E31: 0 | F31: 2 | G31: 0 | H31: 2 | I31: 0 | K31: =DEC2BIN(B31,2) -> 10 | L31: =DEC2BIN(C31,2) -> 00 | M31: =DEC2BIN(D31,2) -> 10 | N31: =DEC2BIN(E31,2) -> 00 | O31: =DEC2BIN(F31,2) -> 10 | P31: =DEC2BIN(G31,2) -> 00 | Q31: =DEC2BIN(H31,2) -> 10 | R31: =DEC2BIN(I31,2) -> 00 | T31: =_xlfn.CONCAT(K31:R31) -> 1000100010001000 | V31: =LEFT(T31,8) -> 10001000 | W31: =RIGHT(T31,8) -> 10001000 | X31: =BIN2HEX(V31,2) -> 88 | Y31: =BIN2HEX(W31,2) -> 88
B32: 2 | C32: 2 | D32: 0 | E32: 0 | F32: 2 | G32: 2 | H32: 0 | I32: 2 | K32: =DEC2BIN(B32,2) -> 10 | L32: =DEC2BIN(C32,2) -> 10 | M32: =DEC2BIN(D32,2) -> 00 | N32: =DEC2BIN(E32,2) -> 00 | O32: =DEC2BIN(F32,2) -> 10 | P32: =DEC2BIN(G32,2) -> 10 | Q32: =DEC2BIN(H32,2) -> 00 | R32: =DEC2BIN(I32,2) -> 10 | T32: =_xlfn.CONCAT(K32:R32) -> 1010000010100010 | V32: =LEFT(T32,8) -> 10100000 | W32: =RIGHT(T32,8) -> 10100010 | X32: =BIN2HEX(V32,2) -> A0 | Y32: =BIN2HEX(W32,2) -> A2
B33: 2 | C33: 0 | D33: 2 | E33: 2 | F33: 0 | G33: 2 | H33: 0 | I33: 0 | K33: =DEC2BIN(B33,2) -> 10 | L33: =DEC2BIN(C33,2) -> 00 | M33: =DEC2BIN(D33,2) -> 10 | N33: =DEC2BIN(E33,2) -> 10 | O33: =DEC2BIN(F33,2) -> 00 | P33: =DEC2BIN(G33,2) -> 10 | Q33: =DEC2BIN(H33,2) -> 00 | R33: =DEC2BIN(I33,2) -> 00 | T33: =_xlfn.CONCAT(K33:R33) -> 1000101000100000 | V33: =LEFT(T33,8) -> 10001010 | W33: =RIGHT(T33,8) -> 00100000 | X33: =BIN2HEX(V33,2) -> 8A | Y33: =BIN2HEX(W33,2) -> 20
B34: 0 | C34: 2 | D34: 0 | E34: 0 | F34: 2 | G34: 0 | H34: 2 | I34: 0 | K34: =DEC2BIN(B34,2) -> 00 | L34: =DEC2BIN(C34,2) -> 10 | M34: =DEC2BIN(D34,2) -> 00 | N34: =DEC2BIN(E34,2) -> 00 | O34: =DEC2BIN(F34,2) -> 10 | P34: =DEC2BIN(G34,2) -> 00 | Q34: =DEC2BIN(H34,2) -> 10 | R34: =DEC2BIN(I34,2) -> 00 | T34: =_xlfn.CONCAT(K34:R34) -> 0010000010001000 | V34: =LEFT(T34,8) -> 00100000 | W34: =RIGHT(T34,8) -> 10001000 | X34: =BIN2HEX(V34,2) -> 20 | Y34: =BIN2HEX(W34,2) -> 88
A35: Boulder 1 | AJ35: =";"&PROPER(A35) -> ;Boulder 1
B36: 0 | C36: 0 | D36: 3 | E36: 3 | F36: 3 | G36: 0 | H36: 0 | I36: 0 | K36: =DEC2BIN(B36,2) -> 00 | L36: =DEC2BIN(C36,2) -> 00 | M36: =DEC2BIN(D36,2) -> 11 | N36: =DEC2BIN(E36,2) -> 11 | O36: =DEC2BIN(F36,2) -> 11 | P36: =DEC2BIN(G36,2) -> 00 | Q36: =DEC2BIN(H36,2) -> 00 | R36: =DEC2BIN(I36,2) -> 00 | T36: =_xlfn.CONCAT(K36:R36) -> 0000111111000000 | V36: =LEFT(T36,8) -> 00001111 | W36: =RIGHT(T36,8) -> 11000000 | X36: =BIN2HEX(V36,2) -> 0F | Y36: =BIN2HEX(W36,2) -> C0 | AA36: {=TRANSPOSE(X36:X43)} -> 0F | AB36: 37 | AC36: ED | AD36: 79 | AE36: 56 | AF36: 65 | AG36: 5A | AH36: 55 | AJ36: =LOWER("!byte $"&AA36&", $"&AB36&", $"&AC36&", $"&AD36&", $"&AE36&", $"&AF36&", $"&AG36&", $"&AH36) -> !byte $0f, $37, $ed, $79, $56, $65, $5a, $55
B37: 0 | C37: 3 | D37: 1 | E37: 3 | F37: 2 | G37: 3 | H37: 0 | I37: 0 | K37: =DEC2BIN(B37,2) -> 00 | L37: =DEC2BIN(C37,2) -> 11 | M37: =DEC2BIN(D37,2) -> 01 | N37: =DEC2BIN(E37,2) -> 11 | O37: =DEC2BIN(F37,2) -> 10 | P37: =DEC2BIN(G37,2) -> 11 | Q37: =DEC2BIN(H37,2) -> 00 | R37: =DEC2BIN(I37,2) -> 00 | T37: =_xlfn.CONCAT(K37:R37) -> 0011011110110000 | V37: =LEFT(T37,8) -> 00110111 | W37: =RIGHT(T37,8) -> 10110000 | X37: =BIN2HEX(V37,2) -> 37 | Y37: =BIN2HEX(W37,2) -> B0 | AA37: {=TRANSPOSE(X44:X51)} -> 45 | AB37: 51 | AC37: 45 | AD37: 51 | AE37: 54 | AF37: 15 | AG37: 04 | AH37: 01 | AJ37: =LOWER("!byte $"&AA37&", $"&AB37&", $"&AC37&", $"&AD37&", $"&AE37&", $"&AF37&", $"&AG37&", $"&AH37) -> !byte $45, $51, $45, $51, $54, $15, $04, $01
B38: 3 | C38: 2 | D38: 3 | E38: 1 | F38: 3 | G38: 3 | H38: 3 | I38: 0 | K38: =DEC2BIN(B38,2) -> 11 | L38: =DEC2BIN(C38,2) -> 10 | M38: =DEC2BIN(D38,2) -> 11 | N38: =DEC2BIN(E38,2) -> 01 | O38: =DEC2BIN(F38,2) -> 11 | P38: =DEC2BIN(G38,2) -> 11 | Q38: =DEC2BIN(H38,2) -> 11 | R38: =DEC2BIN(I38,2) -> 00 | T38: =_xlfn.CONCAT(K38:R38) -> 1110110111111100 | V38: =LEFT(T38,8) -> 11101101 | W38: =RIGHT(T38,8) -> 11111100 | X38: =BIN2HEX(V38,2) -> ED | Y38: =BIN2HEX(W38,2) -> FC | AA38: {=TRANSPOSE(Y36:Y43)} -> C0 | AB38: B0 | AC38: FC | AD38: BF | AE38: 7F | AF38: 67 | AG38: 5F | AH38: 67 | AJ38: =LOWER("!byte $"&AA38&", $"&AB38&", $"&AC38&", $"&AD38&", $"&AE38&", $"&AF38&", $"&AG38&", $"&AH38) -> !byte $c0, $b0, $fc, $bf, $7f, $67, $5f, $67
B39: 1 | C39: 3 | D39: 2 | E39: 1 | F39: 2 | G39: 3 | H39: 3 | I39: 3 | K39: =DEC2BIN(B39,2) -> 01 | L39: =DEC2BIN(C39,2) -> 11 | M39: =DEC2BIN(D39,2) -> 10 | N39: =DEC2BIN(E39,2) -> 01 | O39: =DEC2BIN(F39,2) -> 10 | P39: =DEC2BIN(G39,2) -> 11 | Q39: =DEC2BIN(H39,2) -> 11 | R39: =DEC2BIN(I39,2) -> 11 | T39: =_xlfn.CONCAT(K39:R39) -> 0111100110111111 | V39: =LEFT(T39,8) -> 01111001 | W39: =RIGHT(T39,8) -> 10111111 | X39: =BIN2HEX(V39,2) -> 79 | Y39: =BIN2HEX(W39,2) -> BF | AA39: {=TRANSPOSE(Y44:Y51)} -> 56 | AB39: 66 | AC39: 55 | AD39: 55 | AE39: 54 | AF39: 54 | AG39: 90 | AH39: 40 | AJ39: =LOWER("!byte $"&AA39&", $"&AB39&", $"&AC39&", $"&AD39&", $"&AE39&", $"&AF39&", $"&AG39&", $"&AH39) -> !byte $56, $66, $55, $55, $54, $54, $90, $40
B40: 1 | C40: 1 | D40: 1 | E40: 2 | F40: 1 | G40: 3 | H40: 3 | I40: 3 | K40: =DEC2BIN(B40,2) -> 01 | L40: =DEC2BIN(C40,2) -> 01 | M40: =DEC2BIN(D40,2) -> 01 | N40: =DEC2BIN(E40,2) -> 10 | O40: =DEC2BIN(F40,2) -> 01 | P40: =DEC2BIN(G40,2) -> 11 | Q40: =DEC2BIN(H40,2) -> 11 | R40: =DEC2BIN(I40,2) -> 11 | T40: =_xlfn.CONCAT(K40:R40) -> 0101011001111111 | V40: =LEFT(T40,8) -> 01010110 | W40: =RIGHT(T40,8) -> 01111111 | X40: =BIN2HEX(V40,2) -> 56 | Y40: =BIN2HEX(W40,2) -> 7F
...

Sheet Vic colour ref
A1: Sprite colour code | B1: Source | C1: Source address | D1: Bits | E1: Purpose | F1: Colours available | H1: Colour code | I1: Colour
A2: 0 | B2: Background | C2: 36879 | D2: 00 | E2: Black. Always black in this case (and no black is used elsewhere) | F2: First 8 (when having black background, otherwise 16) | H2: 0 | I2: black
A3: 1 | B3: Border | C3: 36879 | D3: 01 | E3: Group 1 for most of titanium walls, rocks, amoeba; part of rockford, diamonds | F3: First 8 | H3: 1 | I3: white
A4: 2 | B4: Foreground | C4: Colour Map | D4: 10 | E4: Group 2 earth | F4: First 8 | H4: 2 | I4: red
A5: 3 | B5: Aux | C5: 36878 | D5: 11 | E5: Group 3 most of walls, rockford; part of rocks, diamonds | F5: All 16 | H5: 3 | I5: cyan
H6: 4 | I6: purple
H7: 5 | I7: green
H8: 6 | I8: blue
H9: 7 | I9: yellow
H10: 8 | I10: orange
H11: 9 | I11: lt.orange
H12: 10 | I12: pink
H13: 11 | I13: lt.cyan
H14: 12 | I14: lt.purple
H15: 13 | I15: lt.green
H16: 14 | I16: lt.blue
H17: 15 | I17: lt.yellow

Sheet Cave colours
A1: Group 1 for most of titanium walls, rocks, amoeba; part of rockford, diamonds | B1: Group 2 earth | C1: Group 3 most of walls, rockford; part of rocks, diamonds
A2: G1 | B2: G2 | C2: G3 | D2: c1 | E2: c2 | F2: c3 | G2: config json colour_schemes | H2: colour group | I2: order
A3: cyan | B3: green | C3: white | D3: =_xlfn.XLOOKUP(A3,'Vic colour ref'!I:I,'Vic colour ref'!H:H,"") -> 3 | E3: =_xlfn.XLOOKUP(B3,'Vic colour ref'!I:I,'Vic colour ref'!H:H,"") -> 5 | F3: =_xlfn.XLOOKUP(C3,'Vic colour ref'!I:I,'Vic colour ref'!H:H,"") -> 1 | G3: =""""&I3&""": {""code"": ["&D3&","&E3&","&F3&"], ""colours"": ["""&A3&""","""&B3&""","""&C3&"""]}," -> "1": {"code": [3,5,1], "colours": ["cyan","green","white"]}, | H3: =PROPER(A3)&" "&PROPER(B3)&" "&PROPER(C3) -> Cyan Green White | I3: 1
A4: red | B4: blue | C4: lt.purple | D4: =_xlfn.XLOOKUP(A4,'Vic colour ref'!I:I,'Vic colour ref'!H:H,"") -> 2 | E4: =_xlfn.XLOOKUP(B4,'Vic colour ref'!I:I,'Vic colour ref'!H:H,"") -> 6 | F4: =_xlfn.XLOOKUP(C4,'Vic colour ref'!I:I,'Vic colour ref'!H:H,"") -> 12 | G4: =""""&I4&""": {""code"": ["&D4&","&E4&","&F4&"], ""colours"": ["""&A4&""","""&B4&""","""&C4&"""]}," -> "2": {"code": [2,6,12], "colours": ["red","blue","lt.purple"]}, | H4: =PROPER(A4)&" "&PROPER(B4)&" "&PROPER(C4) -> Red Blue Lt.Purple | I4: 2
A5: purple | B5: cyan | C5: white | D5: =_xlfn.XLOOKUP(A5,'Vic colour ref'!I:I,'Vic colour ref'!H:H,"") -> 4 | E5: =_xlfn.XLOOKUP(B5,'Vic colour ref'!I:I,'Vic colour ref'!H:H,"") -> 3 | F5: =_xlfn.XLOOKUP(C5,'Vic colour ref'!I:I,'Vic colour ref'!H:H,"") -> 1 | G5: =""""&I5&""": {""code"": ["&D5&","&E5&","&F5&"], ""colours"": ["""&A5&""","""&B5&""","""&C5&"""]}," -> "3": {"code": [4,3,1], "colours": ["purple","cyan","white"]}, | H5: =PROPER(A5)&" "&PROPER(B5)&" "&PROPER(C5) -> Purple Cyan White | I5: 3
A6: cyan | B6: green | C6: pink | D6: =_xlfn.XLOOKUP(A6,'Vic colour ref'!I:I,'Vic colour ref'!H:H,"") -> 3 | E6: =_xlfn.XLOOKUP(B6,'Vic colour ref'!I:I,'Vic colour ref'!H:H,"") -> 5 | F6: =_xlfn.XLOOKUP(C6,'Vic colour ref'!I:I,'Vic colour ref'!H:H,"") -> 10 | G6: =""""&I6&""": {""code"": ["&D6&","&E6&","&F6&"], ""colours"": ["""&A6&""","""&B6&""","""&C6&"""]}," -> "4": {"code": [3,5,10], "colours": ["cyan","green","pink"]}, | H6: =PROPER(A6)&" "&PROPER(B6)&" "&PROPER(C6) -> Cyan Green Pink | I6: 4
A7: purple | B7: blue | C7: white | D7: =_xlfn.XLOOKUP(A7,'Vic colour ref'!I:I,'Vic colour ref'!H:H,"") -> 4 | E7: =_xlfn.XLOOKUP(B7,'Vic colour ref'!I:I,'Vic colour ref'!H:H,"") -> 6 | F7: =_xlfn.XLOOKUP(C7,'Vic colour ref'!I:I,'Vic colour ref'!H:H,"") -> 1 | G7: =""""&I7&""": {""code"": ["&D7&","&E7&","&F7&"], ""colours"": ["""&A7&""","""&B7&""","""&C7&"""]}," -> "5": {"code": [4,6,1], "colours": ["purple","blue","white"]}, | H7: =PROPER(A7)&" "&PROPER(B7)&" "&PROPER(C7) -> Purple Blue White | I7: 5
A8: cyan | B8: purple | C8: pink | D8: =_xlfn.XLOOKUP(A8,'Vic colour ref'!I:I,'Vic colour ref'!H:H,"") -> 3 | E8: =_xlfn.XLOOKUP(B8,'Vic colour ref'!I:I,'Vic colour ref'!H:H,"") -> 4 | F8: =_xlfn.XLOOKUP(C8,'Vic colour ref'!I:I,'Vic colour ref'!H:H,"") -> 10 | G8: =""""&I8&""": {""code"": ["&D8&","&E8&","&F8&"], ""colours"": ["""&A8&""","""&B8&""","""&C8&"""]}," -> "6": {"code": [3,4,10], "colours": ["cyan","purple","pink"]}, | H8: =PROPER(A8)&" "&PROPER(B8)&" "&PROPER(C8) -> Cyan Purple Pink | I8: 6
A9: red | B9: green | C9: white | D9: =_xlfn.XLOOKUP(A9,'Vic colour ref'!I:I,'Vic colour ref'!H:H,"") -> 2 | E9: =_xlfn.XLOOKUP(B9,'Vic colour ref'!I:I,'Vic colour ref'!H:H,"") -> 5 | F9: =_xlfn.XLOOKUP(C9,'Vic colour ref'!I:I,'Vic colour ref'!H:H,"") -> 1 | G9: =""""&I9&""": {""code"": ["&D9&","&E9&","&F9&"], ""colours"": ["""&A9&""","""&B9&""","""&C9&"""]}," -> "7": {"code": [2,5,1], "colours": ["red","green","white"]}, | H9: =PROPER(A9)&" "&PROPER(B9)&" "&PROPER(C9) -> Red Green White | I9: 7
A10: cyan | B10: blue | C10: pink | D10: =_xlfn.XLOOKUP(A10,'Vic colour ref'!I:I,'Vic colour ref'!H:H,"") -> 3 | E10: =_xlfn.XLOOKUP(B10,'Vic colour ref'!I:I,'Vic colour ref'!H:H,"") -> 6 | F10: =_xlfn.XLOOKUP(C10,'Vic colour ref'!I:I,'Vic colour ref'!H:H,"") -> 10 | G10: =""""&I10&""": {""code"": ["&D10&","&E10&","&F10&"], ""colours"": ["""&A10&""","""&B10&""","""&C10&"""]}," -> "8": {"code": [3,6,10], "colours": ["cyan","blue","pink"]}, | H10: =PROPER(A10)&" "&PROPER(B10)&" "&PROPER(C10) -> Cyan Blue Pink | I10: 8
A11: purple | B11: green | C11: lt.orange | D11: =_xlfn.XLOOKUP(A11,'Vic colour ref'!I:I,'Vic colour ref'!H:H,"") -> 4 | E11: =_xlfn.XLOOKUP(B11,'Vic colour ref'!I:I,'Vic colour ref'!H:H,"") -> 5 | F11: =_xlfn.XLOOKUP(C11,'Vic colour ref'!I:I,'Vic colour ref'!H:H,"") -> 9 | G11: =""""&I11&""": {""code"": ["&D11&","&E11&","&F11&"], ""colours"": ["""&A11&""","""&B11&""","""&C11&"""]}," -> "9": {"code": [4,5,9], "colours": ["purple","green","lt.orange"]}, | H11: =PROPER(A11)&" "&PROPER(B11)&" "&PROPER(C11) -> Purple Green Lt.Orange | I11: 9
A12: cyan | B12: red | C12: white | D12: =_xlfn.XLOOKUP(A12,'Vic colour ref'!I:I,'Vic colour ref'!H:H,"") -> 3 | E12: =_xlfn.XLOOKUP(B12,'Vic colour ref'!I:I,'Vic colour ref'!H:H,"") -> 2 | F12: =_xlfn.XLOOKUP(C12,'Vic colour ref'!I:I,'Vic colour ref'!H:H,"") -> 1 | G12: =""""&I12&""": {""code"": ["&D12&","&E12&","&F12&"], ""colours"": ["""&A12&""","""&B12&""","""&C12&"""]}," -> "10": {"code": [3,2,1], "colours": ["cyan","red","white"]}, | H12: =PROPER(A12)&" "&PROPER(B12)&" "&PROPER(C12) -> Cyan Red White | I12: 10
A13: purple | B13: green | C13: pink | D13: =_xlfn.XLOOKUP(A13,'Vic colour ref'!I:I,'Vic colour ref'!H:H,"") -> 4 | E13: =_xlfn.XLOOKUP(B13,'Vic colour ref'!I:I,'Vic colour ref'!H:H,"") -> 5 | F13: =_xlfn.XLOOKUP(C13,'Vic colour ref'!I:I,'Vic colour ref'!H:H,"") -> 10 | G13: =""""&I13&""": {""code"": ["&D13&","&E13&","&F13&"], ""colours"": ["""&A13&""","""&B13&""","""&C13&"""]}," -> "11": {"code": [4,5,10], "colours": ["purple","green","pink"]}, | H13: =PROPER(A13)&" "&PROPER(B13)&" "&PROPER(C13) -> Purple Green Pink | I13: 11
A14: cyan | B14: purple | C14: white | D14: =_xlfn.XLOOKUP(A14,'Vic colour ref'!I:I,'Vic colour ref'!H:H,"") -> 3 | E14: =_xlfn.XLOOKUP(B14,'Vic colour ref'!I:I,'Vic colour ref'!H:H,"") -> 4 | F14: =_xlfn.XLOOKUP(C14,'Vic colour ref'!I:I,'Vic colour ref'!H:H,"") -> 1 | G14: =""""&I14&""": {""code"": ["&D14&","&E14&","&F14&"], ""colours"": ["""&A14&""","""&B14&""","""&C14&"""]}," -> "12": {"code": [3,4,1], "colours": ["cyan","purple","white"]}, | H14: =PROPER(A14)&" "&PROPER(B14)&" "&PROPER(C14) -> Cyan Purple White | I14: 12
... A23: purple | B23: red | C23: white | D23: =_xlfn.XLOOKUP(A23,'Vic colour ref'!I:I,'Vic colour ref'!H:H,"") -> 4 | E23: =_xlfn.XLOOKUP(B23,'Vic colour ref'!I:I,'Vic colour ref'!H:H,"") -> 2 | F23: =_xlfn.XLOOKUP(C23,'Vic colour ref'!I:I,'Vic colour ref'!H:H,"") -> 1 | G23: =""""&I23&""": {""code"": ["&D23&","&E23&","&F23&"], ""colours"": ["""&A23&""","""&B23&""","""&C23&"""]}," -> "21": {"code": [4,2,1], "colours": ["purple","red","white"]}, | H23: =PROPER(A23)&" "&PROPER(B23)&" "&PROPER(C23) -> Purple Red White | I23: 21
A25: white | B25: blue | C25: lt.purple | D25: =_xlfn.XLOOKUP(A25,'Vic colour ref'!I:I,'Vic colour ref'!H:H,"") -> 1 | E25: =_xlfn.XLOOKUP(B25,'Vic colour ref'!I:I,'Vic colour ref'!H:H,"") -> 6 | F25: =_xlfn.XLOOKUP(C25,'Vic colour ref'!I:I,'Vic colour ref'!H:H,"") -> 12 | G25: =""""&I25&""": {""code"": ["&D25&","&E25&","&F25&"], ""colours"": ["""&A25&""","""&B25&""","""&C25&"""]}," -> "Not selected": {"code": [1,6,12], "colours": ["white","blue","lt.purple"]}, | H25: =PROPER(A25)&" "&PROPER(B25)&" "&PROPER(C25) -> White Blue Lt.Purple | I25: Not selected
A26: white | B26: red | C26: lt.orange | D26: =_xlfn.XLOOKUP(A26,'Vic colour ref'!I:I,'Vic colour ref'!H:H,"") -> 1 | E26: =_xlfn.XLOOKUP(B26,'Vic colour ref'!I:I,'Vic colour ref'!H:H,"") -> 2 | F26: =_xlfn.XLOOKUP(C26,'Vic colour ref'!I:I,'Vic colour ref'!H:H,"") -> 9 | G26: =""""&I26&""": {""code"": ["&D26&","&E26&","&F26&"], ""colours"": ["""&A26&""","""&B26&""","""&C26&"""]}," -> "Not selected": {"code": [1,2,9], "colours": ["white","red","lt.orange"]}, | H26: =PROPER(A26)&" "&PROPER(B26)&" "&PROPER(C26) -> White Red Lt.Orange | I26: Not selected
A27: white | B27: red | C27: pink | D27: =_xlfn.XLOOKUP(A27,'Vic colour ref'!I:I,'Vic colour ref'!H:H,"") -> 1 | E27: =_xlfn.XLOOKUP(B27,'Vic colour ref'!I:I,'Vic colour ref'!H:H,"") -> 2 | F27: =_xlfn.XLOOKUP(C27,'Vic colour ref'!I:I,'Vic colour ref'!H:H,"") -> 10 | G27: =""""&I27&""": {""code"": ["&D27&","&E27&","&F27&"], ""colours"": ["""&A27&""","""&B27&""","""&C27&"""]}," -> "Not selected": {"code": [1,2,10], "colours": ["white","red","pink"]}, | H27: =PROPER(A27)&" "&PROPER(B27)&" "&PROPER(C27) -> White Red Pink | I27: Not selected
A28: white | B28: red | C28: lt.cyan | D28: =_xlfn.XLOOKUP(A28,'Vic colour ref'!I:I,'Vic colour ref'!H:H,"") -> 1 | E28: =_xlfn.XLOOKUP(B28,'Vic colour ref'!I:I,'Vic colour ref'!H:H,"") -> 2 | F28: =_xlfn.XLOOKUP(C28,'Vic colour ref'!I:I,'Vic colour ref'!H:H,"") -> 11 | G28: =""""&I28&""": {""code"": ["&D28&","&E28&","&F28&"], ""colours"": ["""&A28&""","""&B28&""","""&C28&"""]}," -> "Not selected": {"code": [1,2,11], "colours": ["white","red","lt.cyan"]}, | H28: =PROPER(A28)&" "&PROPER(B28)&" "&PROPER(C28) -> White Red Lt.Cyan | I28: Not selected
A29: white | B29: red | C29: lt.purple | D29: =_xlfn.XLOOKUP(A29,'Vic colour ref'!I:I,'Vic colour ref'!H:H,"") -> 1 | E29: =_xlfn.XLOOKUP(B29,'Vic colour ref'!I:I,'Vic colour ref'!H:H,"") -> 2 | F29: =_xlfn.XLOOKUP(C29,'Vic colour ref'!I:I,'Vic colour ref'!H:H,"") -> 12 | G29: =""""&I29&""": {""code"": ["&D29&","&E29&","&F29&"], ""colours"": ["""&A29&""","""&B29&""","""&C29&"""]}," -> "Not selected": {"code": [1,2,12], "colours": ["white","red","lt.purple"]}, | H29: =PROPER(A29)&" "&PROPER(B29)&" "&PROPER(C29) -> White Red Lt.Purple | I29: Not selected
A30: white | B30: red | C30: lt.blue | D30: =_xlfn.XLOOKUP(A30,'Vic colour ref'!I:I,'Vic colour ref'!H:H,"") -> 1 | E30: =_xlfn.XLOOKUP(B30,'Vic colour ref'!I:I,'Vic colour ref'!H:H,"") -> 2 | F30: =_xlfn.XLOOKUP(C30,'Vic colour ref'!I:I,'Vic colour ref'!H:H,"") -> 14 | G30: =""""&I30&""": {""code"": ["&D30&","&E30&","&F30&"], ""colours"": ["""&A30&""","""&B30&""","""&C30&"""]}," -> "Not selected": {"code": [1,2,14], "colours": ["white","red","lt.blue"]}, | H30: =PROPER(A30)&" "&PROPER(B30)&" "&PROPER(C30) -> White Red Lt.Blue | I30: Not selected
A31: white | B31: purple | C31: lt.orange | D31: =_xlfn.XLOOKUP(A31,'Vic colour ref'!I:I,'Vic colour ref'!H:H,"") -> 1 | E31: =_xlfn.XLOOKUP(B31,'Vic colour ref'!I:I,'Vic colour ref'!H:H,"") -> 4 | F31: =_xlfn.XLOOKUP(C31,'Vic colour ref'!I:I,'Vic colour ref'!H:H,"") -> 9 | G31: =""""&I31&""": {""code"": ["&D31&","&E31&","&F31&"], ""colours"": ["""&A31&""","""&B31&""","""&C31&"""]}," -> "Not selected": {"code": [1,4,9], "colours": ["white","purple","lt.orange"]}, | H31: =PROPER(A31)&" "&PROPER(B31)&" "&PROPER(C31) -> White Purple Lt.Orange | I31: Not selected
A32: white | B32: purple | C32: pink | D32: =_xlfn.XLOOKUP(A32,'Vic colour ref'!I:I,'Vic colour ref'!H:H,"") -> 1 | E32: =_xlfn.XLOOKUP(B32,'Vic colour ref'!I:I,'Vic colour ref'!H:H,"") -> 4 | F32: =_xlfn.XLOOKUP(C32,'Vic colour ref'!I:I,'Vic colour ref'!H:H,"") -> 10 | G32: =""""&I32&""": {""code"": ["&D32&","&E32&","&F32&"], ""colours"": ["""&A32&""","""&B32&""","""&C32&"""]}," -> "Not selected": {"code": [1,4,10], "colours": ["white","purple","pink"]}, | H32: =PROPER(A32)&" "&PROPER(B32)&" "&PROPER(C32) -> White Purple Pink | I32: Not selected
A33: white | B33: purple | C33: lt.cyan | D33: =_xlfn.XLOOKUP(A33,'Vic colour ref'!I:I,'Vic colour ref'!H:H,"") -> 1 | E33: =_xlfn.XLOOKUP(B33,'Vic colour ref'!I:I,'Vic colour ref'!H:H,"") -> 4 | F33: =_xlfn.XLOOKUP(C33,'Vic colour ref'!I:I,'Vic colour ref'!H:H,"") -> 11 | G33: =""""&I33&""": {""code"": ["&D33&","&E33&","&F33&"], ""colours"": ["""&A33&""","""&B33&""","""&C33&"""]}," -> "Not selected": {"code": [1,4,11], "colours": ["white","purple","lt.cyan"]}, | H33: =PROPER(A33)&" "&PROPER(B33)&" "&PROPER(C33) -> White Purple Lt.Cyan | I33: Not selected
A34: white | B34: purple | C34: lt.blue | D34: =_xlfn.XLOOKUP(A34,'Vic colour ref'!I:I,'Vic colour ref'!H:H,"") -> 1 | E34: =_xlfn.XLOOKUP(B34,'Vic colour ref'!I:I,'Vic colour ref'!H:H,"") -> 4 | F34: =_xlfn.XLOOKUP(C34,'Vic colour ref'!I:I,'Vic colour ref'!H:H,"") -> 14 | G34: =""""&I34&""": {""code"": ["&D34&","&E34&","&F34&"], ""colours"": ["""&A34&""","""&B34&""","""&C34&"""]}," -> "Not selected": {"code": [1,4,14], "colours": ["white","purple","lt.blue"]}, | H34: =PROPER(A34)&" "&PROPER(B34)&" "&PROPER(C34) -> White Purple Lt.Blue | I34: Not selected
A35: white | B35: green | C35: lt.orange | D35: =_xlfn.XLOOKUP(A35,'Vic colour ref'!I:I,'Vic colour ref'!H:H,"") -> 1 | E35: =_xlfn.XLOOKUP(B35,'Vic colour ref'!I:I,'Vic colour ref'!H:H,"") -> 5 | F35: =_xlfn.XLOOKUP(C35,'Vic colour ref'!I:I,'Vic colour ref'!H:H,"") -> 9 | G35: =""""&I35&""": {""code"": ["&D35&","&E35&","&F35&"], ""colours"": ["""&A35&""","""&B35&""","""&C35&"""]}," -> "Not selected": {"code": [1,5,9], "colours": ["white","green","lt.orange"]}, | H35: =PROPER(A35)&" "&PROPER(B35)&" "&PROPER(C35) -> White Green Lt.Orange | I35: Not selected
A36: white | B36: green | C36: pink | D36: =_xlfn.XLOOKUP(A36,'Vic colour ref'!I:I,'Vic colour ref'!H:H,"") -> 1 | E36: =_xlfn.XLOOKUP(B36,'Vic colour ref'!I:I,'Vic colour ref'!H:H,"") -> 5 | F36: =_xlfn.XLOOKUP(C36,'Vic colour ref'!I:I,'Vic colour ref'!H:H,"") -> 10 | G36: =""""&I36&""": {""code"": ["&D36&","&E36&","&F36&"], ""colours"": ["""&A36&""","""&B36&""","""&C36&"""]}," -> "Not selected": {"code": [1,5,10], "colours": ["white","green","pink"]}, | H36: =PROPER(A36)&" "&PROPER(B36)&" "&PROPER(C36) -> White Green Pink | I36: Not selected
... A83: green | B83: purple | C83: lt.blue | D83: =_xlfn.XLOOKUP(A83,'Vic colour ref'!I:I,'Vic colour ref'!H:H,"") -> 5 | E83: =_xlfn.XLOOKUP(B83,'Vic colour ref'!I:I,'Vic colour ref'!H:H,"") -> 4 | F83: =_xlfn.XLOOKUP(C83,'Vic colour ref'!I:I,'Vic colour ref'!H:H,"") -> 14 | G83: =""""&I83&""": {""code"": ["&D83&","&E83&","&F83&"], ""colours"": ["""&A83&""","""&B83&""","""&C83&"""]}," -> "Not selected": {"code": [5,4,14], "colours": ["green","purple","lt.blue"]}, | H83: =PROPER(A83)&" "&PROPER(B83)&" "&PROPER(C83) -> Green Purple Lt.Blue | I83: Not selected

Sheet LowHighSplit
A1: Start value (hex) | B1: Increment (dec) | C1: Dec | D1: Hex | E1: High | F1: Low
A2: 3e00 | B2: 448 | C2: =HEX2DEC(A2) -> 15872 | D2: =DEC2HEX(C2,4) -> 3E00 | E2: ="$"&LOWER(LEFT(D2,2)) -> $3e | F2: ="$"&LOWER(MID(D2,3,2)) -> $00 | H2: high
C3: =C2+$B$2 -> 16320 | D3: =DEC2HEX(C3,4) -> 3FC0 | E3: ="$"&LOWER(LEFT(D3,2)) -> $3f | F3: ="$"&LOWER(MID(D3,3,2)) -> $c0 | H3: {=CONCATENATE(TRANSPOSE(E2:E25),", ")} -> $3e, | I3: $3f, | J3: $41, | K3: $43, | L3: $45, | M3: $46, | N3: $48, | O3: $4a, | P3: $4c, | Q3: $4d, | R3: $4f, | S3: $51, | T3: $53, | U3: $54, | V3: $56, | W3: $58, | X3: $5a, | Y3: $5b, | Z3: $5d, | AA3: $5f, | AB3: $61, | AC3: $62, | AD3: $64, | AE3: $66,
C4: =C3+$B$2 -> 16768 | D4: =DEC2HEX(C4,4) -> 4180 | E4: ="$"&LOWER(LEFT(D4,2)) -> $41 | F4: ="$"&LOWER(MID(D4,3,2)) -> $80
C5: =C4+$B$2 -> 17216 | D5: =DEC2HEX(C5,4) -> 4340 | E5: ="$"&LOWER(LEFT(D5,2)) -> $43 | F5: ="$"&LOWER(MID(D5,3,2)) -> $40 | H5: low
C6: =C5+$B$2 -> 17664 | D6: =DEC2HEX(C6,4) -> 4500 | E6: ="$"&LOWER(LEFT(D6,2)) -> $45 | F6: ="$"&LOWER(MID(D6,3,2)) -> $00 | H6: {=CONCATENATE(TRANSPOSE(F2:F25),", ")} -> $00, | I6: $c0, | J6: $80, | K6: $40, | L6: $00, | M6: $c0, | N6: $80, | O6: $40, | P6: $00, | Q6: $c0, | R6: $80, | S6: $40, | T6: $00, | U6: $c0, | V6: $80, | W6: $40, | X6: $00, | Y6: $c0, | Z6: $80, | AA6: $40, | AB6: $00, | AC6: $c0, | AD6: $80, | AE6: $40,
C7: =C6+$B$2 -> 18112 | D7: =DEC2HEX(C7,4) -> 46C0 | E7: ="$"&LOWER(LEFT(D7,2)) -> $46 | F7: ="$"&LOWER(MID(D7,3,2)) -> $c0
C8: =C7+$B$2 -> 18560 | D8: =DEC2HEX(C8,4) -> 4880 | E8: ="$"&LOWER(LEFT(D8,2)) -> $48 | F8: ="$"&LOWER(MID(D8,3,2)) -> $80
C9: =C8+$B$2 -> 19008 | D9: =DEC2HEX(C9,4) -> 4A40 | E9: ="$"&LOWER(LEFT(D9,2)) -> $4a | F9: ="$"&LOWER(MID(D9,3,2)) -> $40
C10: =C9+$B$2 -> 19456 | D10: =DEC2HEX(C10,4) -> 4C00 | E10: ="$"&LOWER(LEFT(D10,2)) -> $4c | F10: ="$"&LOWER(MID(D10,3,2)) -> $00
C11: =C10+$B$2 -> 19904 | D11: =DEC2HEX(C11,4) -> 4DC0 | E11: ="$"&LOWER(LEFT(D11,2)) -> $4d | F11: ="$"&LOWER(MID(D11,3,2)) -> $c0
C12: =C11+$B$2 -> 20352 | D12: =DEC2HEX(C12,4) -> 4F80 | E12: ="$"&LOWER(LEFT(D12,2)) -> $4f | F12: ="$"&LOWER(MID(D12,3,2)) -> $80
C13: =C12+$B$2 -> 20800 | D13: =DEC2HEX(C13,4) -> 5140 | E13: ="$"&LOWER(LEFT(D13,2)) -> $51 | F13: ="$"&LOWER(MID(D13,3,2)) -> $40
C14: =C13+$B$2 -> 21248 | D14: =DEC2HEX(C14,4) -> 5300 | E14: ="$"&LOWER(LEFT(D14,2)) -> $53 | F14: ="$"&LOWER(MID(D14,3,2)) -> $00
C15: =C14+$B$2 -> 21696 | D15: =DEC2HEX(C15,4) -> 54C0 | E15: ="$"&LOWER(LEFT(D15,2)) -> $54 | F15: ="$"&LOWER(MID(D15,3,2)) -> $c0
C16: =C15+$B$2 -> 22144 | D16: =DEC2HEX(C16,4) -> 5680 | E16: ="$"&LOWER(LEFT(D16,2)) -> $56 | F16: ="$"&LOWER(MID(D16,3,2)) -> $80
C17: =C16+$B$2 -> 22592 | D17: =DEC2HEX(C17,4) -> 5840 | E17: ="$"&LOWER(LEFT(D17,2)) -> $58 | F17: ="$"&LOWER(MID(D17,3,2)) -> $40
C18: =C17+$B$2 -> 23040 | D18: =DEC2HEX(C18,4) -> 5A00 | E18: ="$"&LOWER(LEFT(D18,2)) -> $5a | F18: ="$"&LOWER(MID(D18,3,2)) -> $00
... C25: =C24+$B$2 -> 26176 | D25: =DEC2HEX(C25,4) -> 6640 | E25: ="$"&LOWER(LEFT(D25,2)) -> $66 | F25: ="$"&LOWER(MID(D25,3,2)) -> $40
A28: Start value (hex) | B28: Increment (dec) | C28: Dec | D28: Hex | E28: High | F28: Low
A29: 1078 | B29: 48 | C29: =HEX2DEC(A29) -> 4216 | D29: =DEC2HEX(C29,4) -> 1078 | E29: ="$"&LOWER(LEFT(D29,2)) -> $10 | F29: ="$"&LOWER(MID(D29,3,2)) -> $78 | H29: high
C30: =C29+$B$29 -> 4264 | D30: =DEC2HEX(C30,4) -> 10A8 | E30: ="$"&LOWER(LEFT(D30,2)) -> $10 | F30: ="$"&LOWER(MID(D30,3,2)) -> $a8 | H30: {=CONCATENATE(TRANSPOSE(E29:E52),", ")} -> $10, | I30: $10, | J30: $10, | K30: $11, | L30: $11, | M30: $11, | N30: $11, | O30: $11, | P30: $11, | Q30: $12, | R30: $12, | S30: $12, | T30: $12, | U30: $12, | V30: $13, | W30: $13, | X30: $13, | Y30: $13, | Z30: $13, | AA30: $14, | AB30: $14, | AC30: $14, | AD30: $14, | AE30: $14,
C31: =C30+$B$29 -> 4312 | D31: =DEC2HEX(C31,4) -> 10D8 | E31: ="$"&LOWER(LEFT(D31,2)) -> $10 | F31: ="$"&LOWER(MID(D31,3,2)) -> $d8
C32: =C31+$B$29 -> 4360 | D32: =DEC2HEX(C32,4) -> 1108 | E32: ="$"&LOWER(LEFT(D32,2)) -> $11 | F32: ="$"&LOWER(MID(D32,3,2)) -> $08 | H32: low
C33: =C32+$B$29 -> 4408 | D33: =DEC2HEX(C33,4) -> 1138 | E33: ="$"&LOWER(LEFT(D33,2)) -> $11 | F33: ="$"&LOWER(MID(D33,3,2)) -> $38 | H33: {=CONCATENATE(TRANSPOSE(F29:F52),", ")} -> $78, | I33: $a8, | J33: $d8, | K33: $08, | L33: $38, | M33: $68, | N33: $98, | O33: $c8, | P33: $f8, | Q33: $28, | R33: $58, | S33: $88, | T33: $b8, | U33: $e8, | V33: $18, | W33: $48, | X33: $78, | Y33: $a8, | Z33: $d8, | AA33: $08, | AB33: $38, | AC33: $68, | AD33: $98, | AE33: $c8,
C34: =C33+$B$29 -> 4456 | D34: =DEC2HEX(C34,4) -> 1168 | E34: ="$"&LOWER(LEFT(D34,2)) -> $11 | F34: ="$"&LOWER(MID(D34,3,2)) -> $68
C35: =C34+$B$29 -> 4504 | D35: =DEC2HEX(C35,4) -> 1198 | E35: ="$"&LOWER(LEFT(D35,2)) -> $11 | F35: ="$"&LOWER(MID(D35,3,2)) -> $98
C36: =C35+$B$29 -> 4552 | D36: =DEC2HEX(C36,4) -> 11C8 | E36: ="$"&LOWER(LEFT(D36,2)) -> $11 | F36: ="$"&LOWER(MID(D36,3,2)) -> $c8
C37: =C36+$B$29 -> 4600 | D37: =DEC2HEX(C37,4) -> 11F8 | E37: ="$"&LOWER(LEFT(D37,2)) -> $11 | F37: ="$"&LOWER(MID(D37,3,2)) -> $f8
C38: =C37+$B$29 -> 4648 | D38: =DEC2HEX(C38,4) -> 1228 | E38: ="$"&LOWER(LEFT(D38,2)) -> $12 | F38: ="$"&LOWER(MID(D38,3,2)) -> $28
C39: =C38+$B$29 -> 4696 | D39: =DEC2HEX(C39,4) -> 1258 | E39: ="$"&LOWER(LEFT(D39,2)) -> $12 | F39: ="$"&LOWER(MID(D39,3,2)) -> $58
C40: =C39+$B$29 -> 4744 | D40: =DEC2HEX(C40,4) -> 1288 | E40: ="$"&LOWER(LEFT(D40,2)) -> $12 | F40: ="$"&LOWER(MID(D40,3,2)) -> $88
C41: =C40+$B$29 -> 4792 | D41: =DEC2HEX(C41,4) -> 12B8 | E41: ="$"&LOWER(LEFT(D41,2)) -> $12 | F41: ="$"&LOWER(MID(D41,3,2)) -> $b8
C42: =C41+$B$29 -> 4840 | D42: =DEC2HEX(C42,4) -> 12E8 | E42: ="$"&LOWER(LEFT(D42,2)) -> $12 | F42: ="$"&LOWER(MID(D42,3,2)) -> $e8
C43: =C42+$B$29 -> 4888 | D43: =DEC2HEX(C43,4) -> 1318 | E43: ="$"&LOWER(LEFT(D43,2)) -> $13 | F43: ="$"&LOWER(MID(D43,3,2)) -> $18
C44: =C43+$B$29 -> 4936 | D44: =DEC2HEX(C44,4) -> 1348 | E44: ="$"&LOWER(LEFT(D44,2)) -> $13 | F44: ="$"&LOWER(MID(D44,3,2)) -> $48
C45: =C44+$B$29 -> 4984 | D45: =DEC2HEX(C45,4) -> 1378 | E45: ="$"&LOWER(LEFT(D45,2)) -> $13 | F45: ="$"&LOWER(MID(D45,3,2)) -> $78
... C52: =C51+$B$29 -> 5320 | D52: =DEC2HEX(C52,4) -> 14C8 | E52: ="$"&LOWER(LEFT(D52,2)) -> $14 | F52: ="$"&LOWER(MID(D52,3,2)) -> $c8

Sheet Status
A1: D | B1: D | E1: B | F1: B | I1: T | J1: I | K1: M | L1: E | O1: C | P1: A | Q1: V | R1: E | T1: A | U1: 1 | W1: R | X1: R
A2: D | B2: D | E2: B | F2: B | I2: t | J2: t | K2: t | Q2: s | R2: s | S2: s | T2: s | U2: s | W2: R | X2: R
A3: d | B3: d | C3: d | E3: b | F3: b | G3: b | W3: r | X3: r
E4: G | F4: O | G4: T | I4: A | J4: L | K4: L | M4: D | N4: I | O4: A | P4: M | Q4: O | R4: N | S4: D | T4: S

Sheet Splash
A1: 0 | B1: 0 | C1: 0 | D1: 0 | E1: 0 | F1: 0 | G1: 0 | H1: 0 | I1: 0 | J1: 0 | K1: 0 | L1: 0 | M1: 0 | N1: 0 | O1: 0 | P1: 0 | Q1: 0 | R1: 0 | S1: 0 | T1: 0 | U1: 0 | V1: 0 | W1: 0 | X1: 0 | Y1: 0 | Z1: 0 | AA1: 0 | AB1: 0 | AC1: 0 | AD1: 0 | AE1: 0 | AF1: 0 | AH1: =_xlfn.XLOOKUP(A1,'Vic colour ref'!$A$2:$A$5,'Vic colour ref'!$D$2:$D$5,"") -> 00 | AI1: =_xlfn.XLOOKUP(B1,'Vic colour ref'!$A$2:$A$5,'Vic colour ref'!$D$2:$D$5,"") -> 00 | AJ1: =_xlfn.XLOOKUP(C1,'Vic colour ref'!$A$2:$A$5,'Vic colour ref'!$D$2:$D$5,"") -> 00 | AK1: =_xlfn.XLOOKUP(D1,'Vic colour ref'!$A$2:$A$5,'Vic colour ref'!$D$2:$D$5,"") -> 00 | AL1: =_xlfn.XLOOKUP(E1,'Vic colour ref'!$A$2:$A$5,'Vic colour ref'!$D$2:$D$5,"") -> 00 | AM1: =_xlfn.XLOOKUP(F1,'Vic colour ref'!$A$2:$A$5,'Vic colour ref'!$D$2:$D$5,"") -> 00 | AN1: =_xlfn.XLOOKUP(G1,'Vic colour ref'!$A$2:$A$5,'Vic colour ref'!$D$2:$D$5,"") -> 00 | AO1: =_xlfn.XLOOKUP(H1,'Vic colour ref'!$A$2:$A$5,'Vic colour ref'!$D$2:$D$5,"") -> 00 | ... BM1: =_xlfn.XLOOKUP(AF1,'Vic colour ref'!$A$2:$A$5,'Vic colour ref'!$D$2:$D$5,"") -> 00 | BO1: =_xlfn.CONCAT(AH1:AK1) -> 00000000 | BP1: =_xlfn.CONCAT(AL1:AO1) -> 00000000 | BQ1: =_xlfn.CONCAT(AP1:AS1) -> 00000000 | BR1: =_xlfn.CONCAT(AT1:AW1) -> 00000000 | BS1: =_xlfn.CONCAT(AX1:BA1) -> 00000000 | BT1: =_xlfn.CONCAT(BB1:BE1) -> 00000000 | BU1: =_xlfn.CONCAT(BF1:BI1) -> 00000000 | BV1: =_xlfn.CONCAT(BJ1:BM1) -> 00000000 | BX1: =BIN2HEX(BO1,2) -> 00 | BY1: =BIN2HEX(BP1,2) -> 00 | BZ1: =BIN2HEX(BQ1,2) -> 00 | CA1: =BIN2HEX(BR1,2) -> 00 | CB1: =BIN2HEX(BS1,2) -> 00 | CC1: =BIN2HEX(BT1,2) -> 00 | CD1: =BIN2HEX(BU1,2) -> 00 | CE1: =BIN2HEX(BV1,2) -> 00 | CG1: {=TRANSPOSE(BX1:BX8)} -> 00 | CH1: 00 | CI1: 03 | CJ1: 03 | CK1: 03 | CL1: 03 | CM1: 03 | CN1: 03 | CP1: =LOWER("!byte $"&CG1&", $"&CH1&", $"&CI1&", $"&CJ1&", $"&CK1&", $"&CL1&", $"&CM1&", $"&CN1) -> !byte $00, $00, $03, $03, $03, $03, $03, $03
A2: 0 | B2: 0 | C2: 0 | D2: 0 | E2: 0 | F2: 0 | G2: 0 | H2: 0 | I2: 0 | J2: 0 | K2: 0 | L2: 0 | M2: 0 | N2: 0 | O2: 0 | P2: 0 | Q2: 0 | R2: 0 | S2: 0 | T2: 0 | U2: 0 | V2: 0 | W2: 0 | X2: 0 | Y2: 0 | Z2: 0 | AA2: 0 | AB2: 0 | AC2: 0 | AD2: 0 | AE2: 0 | AF2: 0 | AH2: =_xlfn.XLOOKUP(A2,'Vic colour ref'!$A$2:$A$5,'Vic colour ref'!$D$2:$D$5,"") -> 00 | AI2: =_xlfn.XLOOKUP(B2,'Vic colour ref'!$A$2:$A$5,'Vic colour ref'!$D$2:$D$5,"") -> 00 | AJ2: =_xlfn.XLOOKUP(C2,'Vic colour ref'!$A$2:$A$5,'Vic colour ref'!$D$2:$D$5,"") -> 00 | AK2: =_xlfn.XLOOKUP(D2,'Vic colour ref'!$A$2:$A$5,'Vic colour ref'!$D$2:$D$5,"") -> 00 | AL2: =_xlfn.XLOOKUP(E2,'Vic colour ref'!$A$2:$A$5,'Vic colour ref'!$D$2:$D$5,"") -> 00 | AM2: =_xlfn.XLOOKUP(F2,'Vic colour ref'!$A$2:$A$5,'Vic colour ref'!$D$2:$D$5,"") -> 00 | AN2: =_xlfn.XLOOKUP(G2,'Vic colour ref'!$A$2:$A$5,'Vic colour ref'!$D$2:$D$5,"") -> 00 | AO2: =_xlfn.XLOOKUP(H2,'Vic colour ref'!$A$2:$A$5,'Vic colour ref'!$D$2:$D$5,"") -> 00 | ... BM2: =_xlfn.XLOOKUP(AF2,'Vic colour ref'!$A$2:$A$5,'Vic colour ref'!$D$2:$D$5,"") -> 00 | BO2: =_xlfn.CONCAT(AH2:AK2) -> 00000000 | BP2: =_xlfn.CONCAT(AL2:AO2) -> 00000000 | BQ2: =_xlfn.CONCAT(AP2:AS2) -> 00000000 | BR2: =_xlfn.CONCAT(AT2:AW2) -> 00000000 | BS2: =_xlfn.CONCAT(AX2:BA2) -> 00000000 | BT2: =_xlfn.CONCAT(BB2:BE2) -> 00000000 | BU2: =_xlfn.CONCAT(BF2:BI2) -> 00000000 | BV2: =_xlfn.CONCAT(BJ2:BM2) -> 00000000 | BX2: =BIN2HEX(BO2,2) -> 00 | BY2: =BIN2HEX(BP2,2) -> 00 | BZ2: =BIN2HEX(BQ2,2) -> 00 | CA2: =BIN2HEX(BR2,2) -> 00 | CB2: =BIN2HEX(BS2,2) -> 00 | CC2: =BIN2HEX(BT2,2) -> 00 | CD2: =BIN2HEX(BU2,2) -> 00 | CE2: =BIN2HEX(BV2,2) -> 00 | CG2: {=TRANSPOSE(BY1:BY8)} -> 00 | CH2: 00 | CI2: F0 | CJ2: F0 | CK2: F0 | CL2: FF | CM2: FF | CN2: FF | CP2: =LOWER("!byte $"&CG2&", $"&CH2&", $"&CI2&", $"&CJ2&", $"&CK2&", $"&CL2&", $"&CM2&", $"&CN2) -> !byte $00, $00, $f0, $f0, $f0, $ff, $ff, $ff
A3: 0 | B3: 0 | C3: 0 | D3: 3 | E3: 3 | F3: 3 | G3: 0 | H3: 0 | I3: 0 | J3: 0 | K3: 0 | L3: 0 | M3: 3 | N3: 3 | O3: 3 | P3: 0 | Q3: 0 | R3: 0 | S3: 0 | T3: 0 | U3: 0 | V3: 0 | W3: 0 | X3: 0 | Y3: 0 | Z3: 0 | AA3: 0 | AB3: 0 | AC3: 0 | AD3: 0 | AE3: 0 | AF3: 0 | AH3: =_xlfn.XLOOKUP(A3,'Vic colour ref'!$A$2:$A$5,'Vic colour ref'!$D$2:$D$5,"") -> 00 | AI3: =_xlfn.XLOOKUP(B3,'Vic colour ref'!$A$2:$A$5,'Vic colour ref'!$D$2:$D$5,"") -> 00 | AJ3: =_xlfn.XLOOKUP(C3,'Vic colour ref'!$A$2:$A$5,'Vic colour ref'!$D$2:$D$5,"") -> 00 | AK3: =_xlfn.XLOOKUP(D3,'Vic colour ref'!$A$2:$A$5,'Vic colour ref'!$D$2:$D$5,"") -> 11 | AL3: =_xlfn.XLOOKUP(E3,'Vic colour ref'!$A$2:$A$5,'Vic colour ref'!$D$2:$D$5,"") -> 11 | AM3: =_xlfn.XLOOKUP(F3,'Vic colour ref'!$A$2:$A$5,'Vic colour ref'!$D$2:$D$5,"") -> 11 | AN3: =_xlfn.XLOOKUP(G3,'Vic colour ref'!$A$2:$A$5,'Vic colour ref'!$D$2:$D$5,"") -> 00 | AO3: =_xlfn.XLOOKUP(H3,'Vic colour ref'!$A$2:$A$5,'Vic colour ref'!$D$2:$D$5,"") -> 00 | ... BM3: =_xlfn.XLOOKUP(AF3,'Vic colour ref'!$A$2:$A$5,'Vic colour ref'!$D$2:$D$5,"") -> 00 | BO3: =_xlfn.CONCAT(AH3:AK3) -> 00000011 | BP3: =_xlfn.CONCAT(AL3:AO3) -> 11110000 | BQ3: =_xlfn.CONCAT(AP3:AS3) -> 00000000 | BR3: =_xlfn.CONCAT(AT3:AW3) -> 11111100 | BS3: =_xlfn.CONCAT(AX3:BA3) -> 00000000 | BT3: =_xlfn.CONCAT(BB3:BE3) -> 00000000 | BU3: =_xlfn.CONCAT(BF3:BI3) -> 00000000 | BV3: =_xlfn.CONCAT(BJ3:BM3) -> 00000000 | BX3: =BIN2HEX(BO3,2) -> 03 | BY3: =BIN2HEX(BP3,2) -> F0 | BZ3: =BIN2HEX(BQ3,2) -> 00 | CA3: =BIN2HEX(BR3,2) -> FC | CB3: =BIN2HEX(BS3,2) -> 00 | CC3: =BIN2HEX(BT3,2) -> 00 | CD3: =BIN2HEX(BU3,2) -> 00 | CE3: =BIN2HEX(BV3,2) -> 00 | CG3: {=TRANSPOSE(BZ1:BZ8)} -> 00 | CH3: 00 | CI3: 00 | CJ3: 00 | CK3: 00 | CL3: FF | CM3: FF | CN3: FF | CP3: =LOWER("!byte $"&CG3&", $"&CH3&", $"&CI3&", $"&CJ3&", $"&CK3&", $"&CL3&", $"&CM3&", $"&CN3) -> !byte $00, $00, $00, $00, $00, $ff, $ff, $ff
A4: 0 | B4: 0 | C4: 0 | D4: 3 | E4: 3 | F4: 3 | G4: 0 | H4: 0 | I4: 0 | J4: 0 | K4: 0 | L4: 0 | M4: 3 | N4: 3 | O4: 3 | P4: 0 | Q4: 0 | R4: 0 | S4: 0 | T4: 0 | U4: 0 | V4: 0 | W4: 0 | X4: 0 | Y4: 0 | Z4: 0 | AA4: 0 | AB4: 0 | AC4: 0 | AD4: 0 | AE4: 0 | AF4: 0 | AH4: =_xlfn.XLOOKUP(A4,'Vic colour ref'!$A$2:$A$5,'Vic colour ref'!$D$2:$D$5,"") -> 00 | AI4: =_xlfn.XLOOKUP(B4,'Vic colour ref'!$A$2:$A$5,'Vic colour ref'!$D$2:$D$5,"") -> 00 | AJ4: =_xlfn.XLOOKUP(C4,'Vic colour ref'!$A$2:$A$5,'Vic colour ref'!$D$2:$D$5,"") -> 00 | AK4: =_xlfn.XLOOKUP(D4,'Vic colour ref'!$A$2:$A$5,'Vic colour ref'!$D$2:$D$5,"") -> 11 | AL4: =_xlfn.XLOOKUP(E4,'Vic colour ref'!$A$2:$A$5,'Vic colour ref'!$D$2:$D$5,"") -> 11 | AM4: =_xlfn.XLOOKUP(F4,'Vic colour ref'!$A$2:$A$5,'Vic colour ref'!$D$2:$D$5,"") -> 11 | AN4: =_xlfn.XLOOKUP(G4,'Vic colour ref'!$A$2:$A$5,'Vic colour ref'!$D$2:$D$5,"") -> 00 | AO4: =_xlfn.XLOOKUP(H4,'Vic colour ref'!$A$2:$A$5,'Vic colour ref'!$D$2:$D$5,"") -> 00 | ... BM4: =_xlfn.XLOOKUP(AF4,'Vic colour ref'!$A$2:$A$5,'Vic colour ref'!$D$2:$D$5,"") -> 00 | BO4: =_xlfn.CONCAT(AH4:AK4) -> 00000011 | BP4: =_xlfn.CONCAT(AL4:AO4) -> 11110000 | BQ4: =_xlfn.CONCAT(AP4:AS4) -> 00000000 | BR4: =_xlfn.CONCAT(AT4:AW4) -> 11111100 | BS4: =_xlfn.CONCAT(AX4:BA4) -> 00000000 | BT4: =_xlfn.CONCAT(BB4:BE4) -> 00000000 | BU4: =_xlfn.CONCAT(BF4:BI4) -> 00000000 | BV4: =_xlfn.CONCAT(BJ4:BM4) -> 00000000 | BX4: =BIN2HEX(BO4,2) -> 03 | BY4: =BIN2HEX(BP4,2) -> F0 | BZ4: =BIN2HEX(BQ4,2) -> 00 | CA4: =BIN2HEX(BR4,2) -> FC | CB4: =BIN2HEX(BS4,2) -> 00 | CC4: =BIN2HEX(BT4,2) -> 00 | CD4: =BIN2HEX(BU4,2) -> 00 | CE4: =BIN2HEX(BV4,2) -> 00 | CG4: {=TRANSPOSE(CA1:CA8)} -> 00 | CH4: 00 | CI4: FC | CJ4: FC | CK4: FC | CL4: FC | CM4: FC | CN4: FC | CP4: =LOWER("!byte $"&CG4&", $"&CH4&", $"&CI4&", $"&CJ4&", $"&CK4&", $"&CL4&", $"&CM4&", $"&CN4) -> !byte $00, $00, $fc, $fc, $fc, $fc, $fc, $fc
A5: 0 | B5: 0 | C5: 0 | D5: 3 | E5: 3 | F5: 3 | G5: 0 | H5: 0 | I5: 0 | J5: 0 | K5: 0 | L5: 0 | M5: 3 | N5: 3 | O5: 3 | P5: 0 | Q5: 0 | R5: 0 | S5: 0 | T5: 0 | U5: 0 | V5: 0 | W5: 0 | X5: 0 | Y5: 0 | Z5: 0 | AA5: 0 | AB5: 0 | AC5: 0 | AD5: 0 | AE5: 0 | AF5: 0 | AH5: =_xlfn.XLOOKUP(A5,'Vic colour ref'!$A$2:$A$5,'Vic colour ref'!$D$2:$D$5,"") -> 00 | AI5: =_xlfn.XLOOKUP(B5,'Vic colour ref'!$A$2:$A$5,'Vic colour ref'!$D$2:$D$5,"") -> 00 | AJ5: =_xlfn.XLOOKUP(C5,'Vic colour ref'!$A$2:$A$5,'Vic colour ref'!$D$2:$D$5,"") -> 00 | AK5: =_xlfn.XLOOKUP(D5,'Vic colour ref'!$A$2:$A$5,'Vic colour ref'!$D$2:$D$5,"") -> 11 | AL5: =_xlfn.XLOOKUP(E5,'Vic colour ref'!$A$2:$A$5,'Vic colour ref'!$D$2:$D$5,"") -> 11 | AM5: =_xlfn.XLOOKUP(F5,'Vic colour ref'!$A$2:$A$5,'Vic colour ref'!$D$2:$D$5,"") -> 11 | AN5: =_xlfn.XLOOKUP(G5,'Vic colour ref'!$A$2:$A$5,'Vic colour ref'!$D$2:$D$5,"") -> 00 | AO5: =_xlfn.XLOOKUP(H5,'Vic colour ref'!$A$2:$A$5,'Vic colour ref'!$D$2:$D$5,"") -> 00 | ... BM5: =_xlfn.XLOOKUP(AF5,'Vic colour ref'!$A$2:$A$5,'Vic colour ref'!$D$2:$D$5,"") -> 00 | BO5: =_xlfn.CONCAT(AH5:AK5) -> 00000011 | BP5: =_xlfn.CONCAT(AL5:AO5) -> 11110000 | BQ5: =_xlfn.CONCAT(AP5:AS5) -> 00000000 | BR5: =_xlfn.CONCAT(AT5:AW5) -> 11111100 | BS5: =_xlfn.CONCAT(AX5:BA5) -> 00000000 | BT5: =_xlfn.CONCAT(BB5:BE5) -> 00000000 | BU5: =_xlfn.CONCAT(BF5:BI5) -> 00000000 | BV5: =_xlfn.CONCAT(BJ5:BM5) -> 00000000 | BX5: =BIN2HEX(BO5,2) -> 03 | BY5: =BIN2HEX(BP5,2) -> F0 | BZ5: =BIN2HEX(BQ5,2) -> 00 | CA5: =BIN2HEX(BR5,2) -> FC | CB5: =BIN2HEX(BS5,2) -> 00 | CC5: =BIN2HEX(BT5,2) -> 00 | CD5: =BIN2HEX(BU5,2) -> 00 | CE5: =BIN2HEX(BV5,2) -> 00 | CG5: {=TRANSPOSE(CB1:CB8)} -> 00 | CH5: 00 | CI5: 00 | CJ5: 00 | CK5: 00 | CL5: 00 | CM5: 00 | CN5: 00 | CP5: =LOWER("!byte $"&CG5&", $"&CH5&", $"&CI5&", $"&CJ5&", $"&CK5&", $"&CL5&", $"&CM5&", $"&CN5) -> !byte $00, $00, $00, $00, $00, $00, $00, $00
A6: 0 | B6: 0 | C6: 0 | D6: 3 | E6: 3 | F6: 3 | G6: 3 | H6: 3 | I6: 3 | J6: 3 | K6: 3 | L6: 3 | M6: 3 | N6: 3 | O6: 3 | P6: 0 | Q6: 0 | R6: 0 | S6: 0 | T6: 0 | U6: 0 | V6: 0 | W6: 0 | X6: 0 | Y6: 0 | Z6: 0 | AA6: 0 | AB6: 0 | AC6: 0 | AD6: 0 | AE6: 0 | AF6: 0 | AH6: =_xlfn.XLOOKUP(A6,'Vic colour ref'!$A$2:$A$5,'Vic colour ref'!$D$2:$D$5,"") -> 00 | AI6: =_xlfn.XLOOKUP(B6,'Vic colour ref'!$A$2:$A$5,'Vic colour ref'!$D$2:$D$5,"") -> 00 | AJ6: =_xlfn.XLOOKUP(C6,'Vic colour ref'!$A$2:$A$5,'Vic colour ref'!$D$2:$D$5,"") -> 00 | AK6: =_xlfn.XLOOKUP(D6,'Vic colour ref'!$A$2:$A$5,'Vic colour ref'!$D$2:$D$5,"") -> 11 | AL6: =_xlfn.XLOOKUP(E6,'Vic colour ref'!$A$2:$A$5,'Vic colour ref'!$D$2:$D$5,"") -> 11 | AM6: =_xlfn.XLOOKUP(F6,'Vic colour ref'!$A$2:$A$5,'Vic colour ref'!$D$2:$D$5,"") -> 11 | AN6: =_xlfn.XLOOKUP(G6,'Vic colour ref'!$A$2:$A$5,'Vic colour ref'!$D$2:$D$5,"") -> 11 | AO6: =_xlfn.XLOOKUP(H6,'Vic colour ref'!$A$2:$A$5,'Vic colour ref'!$D$2:$D$5,"") -> 11 | ... BM6: =_xlfn.XLOOKUP(AF6,'Vic colour ref'!$A$2:$A$5,'Vic colour ref'!$D$2:$D$5,"") -> 00 | BO6: =_xlfn.CONCAT(AH6:AK6) -> 00000011 | BP6: =_xlfn.CONCAT(AL6:AO6) -> 11111111 | BQ6: =_xlfn.CONCAT(AP6:AS6) -> 11111111 | BR6: =_xlfn.CONCAT(AT6:AW6) -> 11111100 | BS6: =_xlfn.CONCAT(AX6:BA6) -> 00000000 | BT6: =_xlfn.CONCAT(BB6:BE6) -> 00000000 | BU6: =_xlfn.CONCAT(BF6:BI6) -> 00000000 | BV6: =_xlfn.CONCAT(BJ6:BM6) -> 00000000 | BX6: =BIN2HEX(BO6,2) -> 03 | BY6: =BIN2HEX(BP6,2) -> FF | BZ6: =BIN2HEX(BQ6,2) -> FF | CA6: =BIN2HEX(BR6,2) -> FC | CB6: =BIN2HEX(BS6,2) -> 00 | CC6: =BIN2HEX(BT6,2) -> 00 | CD6: =BIN2HEX(BU6,2) -> 00 | CE6: =BIN2HEX(BV6,2) -> 00 | CG6: {=TRANSPOSE(CC1:CC8)} -> 00 | CH6: 00 | CI6: 00 | CJ6: 00 | CK6: 00 | CL6: 00 | CM6: 00 | CN6: 00 | CP6: =LOWER("!byte $"&CG6&", $"&CH6&", $"&CI6&", $"&CJ6&", $"&CK6&", $"&CL6&", $"&CM6&", $"&CN6) -> !byte $00, $00, $00, $00, $00, $00, $00, $00
A7: 0 | B7: 0 | C7: 0 | D7: 3 | E7: 3 | F7: 3 | G7: 3 | H7: 3 | I7: 3 | J7: 3 | K7: 3 | L7: 3 | M7: 3 | N7: 3 | O7: 3 | P7: 0 | Q7: 0 | R7: 0 | S7: 0 | T7: 0 | U7: 0 | V7: 0 | W7: 0 | X7: 0 | Y7: 0 | Z7: 0 | AA7: 0 | AB7: 0 | AC7: 0 | AD7: 0 | AE7: 0 | AF7: 0 | AH7: =_xlfn.XLOOKUP(A7,'Vic colour ref'!$A$2:$A$5,'Vic colour ref'!$D$2:$D$5,"") -> 00 | AI7: =_xlfn.XLOOKUP(B7,'Vic colour ref'!$A$2:$A$5,'Vic colour ref'!$D$2:$D$5,"") -> 00 | AJ7: =_xlfn.XLOOKUP(C7,'Vic colour ref'!$A$2:$A$5,'Vic colour ref'!$D$2:$D$5,"") -> 00 | AK7: =_xlfn.XLOOKUP(D7,'Vic colour ref'!$A$2:$A$5,'Vic colour ref'!$D$2:$D$5,"") -> 11 | AL7: =_xlfn.XLOOKUP(E7,'Vic colour ref'!$A$2:$A$5,'Vic colour ref'!$D$2:$D$5,"") -> 11 | AM7: =_xlfn.XLOOKUP(F7,'Vic colour ref'!$A$2:$A$5,'Vic colour ref'!$D$2:$D$5,"") -> 11 | AN7: =_xlfn.XLOOKUP(G7,'Vic colour ref'!$A$2:$A$5,'Vic colour ref'!$D$2:$D$5,"") -> 11 | AO7: =_xlfn.XLOOKUP(H7,'Vic colour ref'!$A$2:$A$5,'Vic colour ref'!$D$2:$D$5,"") -> 11 | ... BM7: =_xlfn.XLOOKUP(AF7,'Vic colour ref'!$A$2:$A$5,'Vic colour ref'!$D$2:$D$5,"") -> 00 | BO7: =_xlfn.CONCAT(AH7:AK7) -> 00000011 | BP7: =_xlfn.CONCAT(AL7:AO7) -> 11111111 | BQ7: =_xlfn.CONCAT(AP7:AS7) -> 11111111 | BR7: =_xlfn.CONCAT(AT7:AW7) -> 11111100 | BS7: =_xlfn.CONCAT(AX7:BA7) -> 00000000 | BT7: =_xlfn.CONCAT(BB7:BE7) -> 00000000 | BU7: =_xlfn.CONCAT(BF7:BI7) -> 00000000 | BV7: =_xlfn.CONCAT(BJ7:BM7) -> 00000000 | BX7: =BIN2HEX(BO7,2) -> 03 | BY7: =BIN2HEX(BP7,2) -> FF | BZ7: =BIN2HEX(BQ7,2) -> FF | CA7: =BIN2HEX(BR7,2) -> FC | CB7: =BIN2HEX(BS7,2) -> 00 | CC7: =BIN2HEX(BT7,2) -> 00 | CD7: =BIN2HEX(BU7,2) -> 00 | CE7: =BIN2HEX(BV7,2) -> 00 | CG7: {=TRANSPOSE(CD1:CD8)} -> 00 | CH7: 00 | CI7: 00 | CJ7: 00 | CK7: 00 | CL7: 00 | CM7: 00 | CN7: 00 | CP7: =LOWER("!byte $"&CG7&", $"&CH7&", $"&CI7&", $"&CJ7&", $"&CK7&", $"&CL7&", $"&CM7&", $"&CN7) -> !byte $00, $00, $00, $00, $00, $00, $00, $00
A8: 0 | B8: 0 | C8: 0 | D8: 3 | E8: 3 | F8: 3 | G8: 3 | H8: 3 | I8: 3 | J8: 3 | K8: 3 | L8: 3 | M8: 3 | N8: 3 | O8: 3 | P8: 0 | Q8: 0 | R8: 0 | S8: 0 | T8: 0 | U8: 0 | V8: 0 | W8: 0 | X8: 0 | Y8: 0 | Z8: 0 | AA8: 0 | AB8: 0 | AC8: 0 | AD8: 0 | AE8: 0 | AF8: 0 | AH8: =_xlfn.XLOOKUP(A8,'Vic colour ref'!$A$2:$A$5,'Vic colour ref'!$D$2:$D$5,"") -> 00 | AI8: =_xlfn.XLOOKUP(B8,'Vic colour ref'!$A$2:$A$5,'Vic colour ref'!$D$2:$D$5,"") -> 00 | AJ8: =_xlfn.XLOOKUP(C8,'Vic colour ref'!$A$2:$A$5,'Vic colour ref'!$D$2:$D$5,"") -> 00 | AK8: =_xlfn.XLOOKUP(D8,'Vic colour ref'!$A$2:$A$5,'Vic colour ref'!$D$2:$D$5,"") -> 11 | AL8: =_xlfn.XLOOKUP(E8,'Vic colour ref'!$A$2:$A$5,'Vic colour ref'!$D$2:$D$5,"") -> 11 | AM8: =_xlfn.XLOOKUP(F8,'Vic colour ref'!$A$2:$A$5,'Vic colour ref'!$D$2:$D$5,"") -> 11 | AN8: =_xlfn.XLOOKUP(G8,'Vic colour ref'!$A$2:$A$5,'Vic colour ref'!$D$2:$D$5,"") -> 11 | AO8: =_xlfn.XLOOKUP(H8,'Vic colour ref'!$A$2:$A$5,'Vic colour ref'!$D$2:$D$5,"") -> 11 | ... BM8: =_xlfn.XLOOKUP(AF8,'Vic colour ref'!$A$2:$A$5,'Vic colour ref'!$D$2:$D$5,"") -> 00 | BO8: =_xlfn.CONCAT(AH8:AK8) -> 00000011 | BP8: =_xlfn.CONCAT(AL8:AO8) -> 11111111 | BQ8: =_xlfn.CONCAT(AP8:AS8) -> 11111111 | BR8: =_xlfn.CONCAT(AT8:AW8) -> 11111100 | BS8: =_xlfn.CONCAT(AX8:BA8) -> 00000000 | BT8: =_xlfn.CONCAT(BB8:BE8) -> 00000000 | BU8: =_xlfn.CONCAT(BF8:BI8) -> 00000000 | BV8: =_xlfn.CONCAT(BJ8:BM8) -> 00000000 | BX8: =BIN2HEX(BO8,2) -> 03 | BY8: =BIN2HEX(BP8,2) -> FF | BZ8: =BIN2HEX(BQ8,2) -> FF | CA8: =BIN2HEX(BR8,2) -> FC | CB8: =BIN2HEX(BS8,2) -> 00 | CC8: =BIN2HEX(BT8,2) -> 00 | CD8: =BIN2HEX(BU8,2) -> 00 | CE8: =BIN2HEX(BV8,2) -> 00 | CG8: {=TRANSPOSE(CE1:CE8)} -> 00 | CH8: 00 | CI8: 00 | CJ8: 00 | CK8: 00 | CL8: 00 | CM8: 00 | CN8: 00 | CP8: =LOWER("!byte $"&CG8&", $"&CH8&", $"&CI8&", $"&CJ8&", $"&CK8&", $"&CL8&", $"&CM8&", $"&CN8) -> !byte $00, $00, $00, $00, $00, $00, $00, $00
